Workbook

Sheet Master Summary
A1: Name | B1: Total Hours | C1: Visual Design | D1: Backend | E1: Web Mobile | F1: Wireframe | G1: Sheet Name
A2: Project Management
A3: Team | B3: Overall
A4: UI/UX Lead | B4: =ROUND((min(F46, G46) * (B$39 / 8)) * 40)
A5: UI/UX Review | B5: =ROUND(B6 * 10%)
A6: Design Hours (Wireframe + Visual Design) | B6: =ROUND(SUM(E55,F55))
A7: UI/UX BA | B7: =ROUND((min(F46, G46) * (B$38 / 8)) * 40)
A8: UI/UX UAT | B8: =(((min(F46, G46) / 2 ) / 2) * 40)
A9: UI/UX Documentation | B9: 0
A10: Development Hours (Web/Mobile + Backend) | B10: =ROUND(SUM(C55,D55))
A11: BA | B11: =ROUND((max(min(B46, C46), min(D46, E46)) * (B$35 / 8)) * 40)
A12: QA | B12: =ROUND((max(min(B46, C46), min(D46, E46)) * (B$37 / 8)) * 40)
A13: UAT | B13: =(((max(min(B46, C46), min(D46, E46)) / 2 ) / 2) * 40)
A14: Lead | B14: =ROUND((max(min(B46, C46), min(D46, E46)) * (B$36 / 8)) * 40)
A15: Documentation | B15: 0
A16: Deployment | B16: 0
A17: Overall | B17: =SUM(B4:B16)
A22: Team Size
A23: Name | B23: Role | C23: Count
A24: Fe | B24: SSE | C24: 0
A25: Fe | B25: SE | C25: 2
A26: Be | B26: SE | C26: 0
A27: Be | B27: SSE | C27: 0
A28: Ux | B28: UIUX_DESIGNER | C28: 2
A33: Team Hours
A34: Team | B34: Hr / Day
A35: ba | B35: 2
A36: lead | B36: 4
A37: qa | B37: 3
A38: uiux_ba | B38: 2
A39: uiux_lead | B39: 2
A44: Project Development Time Line
A45: App Name | B45: FE Min | C45: FE Max | D45: BE Min | E45: BE Max | F45: Design Min | G45: Design Max
A46: Over All | B46: =Round(IFERROR((SUM(C55)/ (SUM(C$24:C25) * 40))), 0) | C46: =Round(IFERROR((SUM(C55)/ (SUM(C$24:C25) * 35))), 0) | D46: =Round(IFERROR((SUM(D55)/ (SUM(C26:C27) * 40))), 0) | E46: =Round(IFERROR((SUM(D55)/ (SUM(C26:C27) * 35))), 0) | F46: =Round(IFERROR((SUM(E55:F55)/ (SUM(C28) * 40))), 0) | G46: =Round(IFERROR((SUM(E55:F55)/ (SUM(C28) * 35))), 0)
A51: App Wise Phase Estimation
A52: Name | B52: Sheet Name | C52: Web/Mobile | D52: Backend | E52: Visual Design | F52: Wireframes | G52: Total Hours
A53: Mobile App | B53: Mobile App - Summary | C53: =INDIRECT("'"&B53&"'!F18") | D53: =INDIRECT("'"&B53&"'!F19") | E53: =INDIRECT("'"&B53&"'!F12") | F53: =INDIRECT("'"&B53&"'!F11") | G53: =sum(C53:F53)
A54: Mobile App - CR | B54: Mobile App - CR - Summary | C54: =INDIRECT("'"&B54&"'!F18") | D54: =INDIRECT("'"&B54&"'!F19") | E54: =INDIRECT("'"&B54&"'!F12") | F54: =INDIRECT("'"&B54&"'!F11") | G54: =sum(C54:F54)
A55: Sub Total | C55: =SUM(C48:C54) | D55: =SUM(D48:D54) | E55: =SUM(E48:E54) | F55: =SUM(F48:F54) | G55: =sum(C55:F55)

Sheet Mobile App - CR - Dev
A1: Module Name | B1: Feature | C1: Sub-Feature | D1: Description | E1: Reference Link | F1: Assumption | G1: Queries | H1: Prototype Link | I1: What to do? | J1: How to do? | K1: Complexity | L1: Priority | M1: Frequency | N1: Design Available | O1: Required Development | P1: NPM Packages | Q1: Wireframes Story Points | R1: =SUM(R2:R1006) | S1: Visual Design Story Points | T1: =SUM(T2:T1006) | U1: Frontend Story Points | V1: =SUM(V2:V1006) | W1: Integration Story Points | X1: =SUM(X2:X1006) | Y1: Backend Story Points | Z1: =SUM(Z2:Z1006) | AA1: =SUM(AA2:AA1006) | AB1: T-Shirt Size | AC1: Tags | AD1: Screen Patterns | AE1: Feature Categories
A2: Testimonials | B2: Listing of carousals | D2: Multiple scrollable cards | K2: Simple | L2: Must Have | Q2: 2 | R2: =Ifs( (Q2 = 'Points-Table'!$A$4), 'Points-Table'!$C$4, (Q2 = 'Points-Table'!$A$5), 'Points-Table'!$C$5, (Q2 = 'Points-Table'!$A$6), 'Points-Table'!$C$6, (Q2 = 'Points-Table'!$A$7), 'Points-Table'!$C$7, (Q2 = 'Points-Table'!$A$8), 'Points-Table'!$C$8, (Q2 = 'Points-Table'!$A$9), 'Points-Table'!$C$9, (Q2 = 'Points-Table'!$A$10), 'Points-Table'!$C$10, (Q2 = 'Points-Table'!$A$11), 'Points-Table'!$C$11, (Q2 = 'Points-Table'!$A$12), 'Points-Table'!$C$12, (Q2 = 'Points-Table'!$A$13), 'Points-Table'!$C$13, true, 0 ) | S2: 3 | T2: =Ifs( (S2 = 'Points-Table'!$A$4), 'Points-Table'!$C$4, (S2 = 'Points-Table'!$A$5), 'Points-Table'!$C$5, (S2 = 'Points-Table'!$A$6), 'Points-Table'!$C$6, (S2 = 'Points-Table'!$A$7), 'Points-Table'!$C$7, (S2 = 'Points-Table'!$A$8), 'Points-Table'!$C$8, (S2 = 'Points-Table'!$A$9), 'Points-Table'!$C$9, (S2 = 'Points-Table'!$A$10), 'Points-Table'!$C$10, (S2 = 'Points-Table'!$A$11), 'Points-Table'!$C$11, (S2 = 'Points-Table'!$A$12), 'Points-Table'!$C$12, (S2 = 'Points-Table'!$A$13), 'Points-Table'!$C$13, true, 0 ) | U2: 3 | V2: =Ifs( (U2 = 'Points-Table'!$A$4), 'Points-Table'!$C$4, (U2 = 'Points-Table'!$A$5), 'Points-Table'!$C$5, (U2 = 'Points-Table'!$A$6), 'Points-Table'!$C$6, (U2 = 'Points-Table'!$A$7), 'Points-Table'!$C$7, (U2 = 'Points-Table'!$A$8), 'Points-Table'!$C$8, (U2 = 'Points-Table'!$A$9), 'Points-Table'!$C$9, (U2 = 'Points-Table'!$A$10), 'Points-Table'!$C$10, (U2 = 'Points-Table'!$A$11), 'Points-Table'!$C$11, (U2 = 'Points-Table'!$A$12), 'Points-Table'!$C$12, (U2 = 'Points-Table'!$A$13), 'Points-Table'!$C$13, true, 0 ) | W2: 0 | X2: =Ifs( (W2 = 'Points-Table'!$A$4), 'Points-Table'!$C$4, (W2 = 'Points-Table'!$A$5), 'Points-Table'!$C$5, (W2 = 'Points-Table'!$A$6), 'Points-Table'!$C$6, (W2 = 'Points-Table'!$A$7), 'Points-Table'!$C$7, (W2 = 'Points-Table'!$A$8), 'Points-Table'!$C$8, (W2 = 'Points-Table'!$A$9), 'Points-Table'!$C$9, (W2 = 'Points-Table'!$A$10), 'Points-Table'!$C$10, (W2 = 'Points-Table'!$A$11), 'Points-Table'!$C$11, (W2 = 'Points-Table'!$A$12), 'Points-Table'!$C$12, (W2 = 'Points-Table'!$A$13), 'Points-Table'!$C$13, true, 0 ) | Z2: =Ifs( (Y2 = 'Points-Table'!$A$4), 'Points-Table'!$C$4, (Y2 = 'Points-Table'!$A$5), 'Points-Table'!$C$5, (Y2 = 'Points-Table'!$A$6), 'Points-Table'!$C$6, (Y2 = 'Points-Table'!$A$7), 'Points-Table'!$C$7, (Y2 = 'Points-Table'!$A$8), 'Points-Table'!$C$8, (Y2 = 'Points-Table'!$A$9), 'Points-Table'!$C$9, (Y2 = 'Points-Table'!$A$10), 'Points-Table'!$C$10, (Y2 = 'Points-Table'!$A$11), 'Points-Table'!$C$11, (Y2 = 'Points-Table'!$A$12), 'Points-Table'!$C$12, (Y2 = 'Points-Table'!$A$13), 'Points-Table'!$C$13, true, 0 ) | AA2: =SUM(V2,X2,Z2) | AB2: =Ifs( ISBETWEEN(AA2, 0, 'Points-Table'!C$20, TRUE, False), 'Points-Table'!A$20, ISBETWEEN(AA2, 'Points-Table'!C$20, 'Points-Table'!C$21, TRUE, False), 'Points-Table'!A$21, ISBETWEEN(AA2, 'Points-Table'!C$22, 10000, TRUE, TRUE), 'Points-Table'!A$22, true, 0)
A3: Testimonials | B3: API Integration | K3: Simple | L3: Must Have | R3: =Ifs( (Q3 = 'Points-Table'!$A$4), 'Points-Table'!$C$4, (Q3 = 'Points-Table'!$A$5), 'Points-Table'!$C$5, (Q3 = 'Points-Table'!$A$6), 'Points-Table'!$C$6, (Q3 = 'Points-Table'!$A$7), 'Points-Table'!$C$7, (Q3 = 'Points-Table'!$A$8), 'Points-Table'!$C$8, (Q3 = 'Points-Table'!$A$9), 'Points-Table'!$C$9, (Q3 = 'Points-Table'!$A$10), 'Points-Table'!$C$10, (Q3 = 'Points-Table'!$A$11), 'Points-Table'!$C$11, (Q3 = 'Points-Table'!$A$12), 'Points-Table'!$C$12, (Q3 = 'Points-Table'!$A$13), 'Points-Table'!$C$13, true, 0 ) | S3: 0 | T3: =Ifs( (S3 = 'Points-Table'!$A$4), 'Points-Table'!$C$4, (S3 = 'Points-Table'!$A$5), 'Points-Table'!$C$5, (S3 = 'Points-Table'!$A$6), 'Points-Table'!$C$6, (S3 = 'Points-Table'!$A$7), 'Points-Table'!$C$7, (S3 = 'Points-Table'!$A$8), 'Points-Table'!$C$8, (S3 = 'Points-Table'!$A$9), 'Points-Table'!$C$9, (S3 = 'Points-Table'!$A$10), 'Points-Table'!$C$10, (S3 = 'Points-Table'!$A$11), 'Points-Table'!$C$11, (S3 = 'Points-Table'!$A$12), 'Points-Table'!$C$12, (S3 = 'Points-Table'!$A$13), 'Points-Table'!$C$13, true, 0 ) | U3: 0 | V3: =Ifs( (U3 = 'Points-Table'!$A$4), 'Points-Table'!$C$4, (U3 = 'Points-Table'!$A$5), 'Points-Table'!$C$5, (U3 = 'Points-Table'!$A$6), 'Points-Table'!$C$6, (U3 = 'Points-Table'!$A$7), 'Points-Table'!$C$7, (U3 = 'Points-Table'!$A$8), 'Points-Table'!$C$8, (U3 = 'Points-Table'!$A$9), 'Points-Table'!$C$9, (U3 = 'Points-Table'!$A$10), 'Points-Table'!$C$10, (U3 = 'Points-Table'!$A$11), 'Points-Table'!$C$11, (U3 = 'Points-Table'!$A$12), 'Points-Table'!$C$12, (U3 = 'Points-Table'!$A$13), 'Points-Table'!$C$13, true, 0 ) | W3: 5 | X3: =Ifs( (W3 = 'Points-Table'!$A$4), 'Points-Table'!$C$4, (W3 = 'Points-Table'!$A$5), 'Points-Table'!$C$5, (W3 = 'Points-Table'!$A$6), 'Points-Table'!$C$6, (W3 = 'Points-Table'!$A$7), 'Points-Table'!$C$7, (W3 = 'Points-Table'!$A$8), 'Points-Table'!$C$8, (W3 = 'Points-Table'!$A$9), 'Points-Table'!$C$9, (W3 = 'Points-Table'!$A$10), 'Points-Table'!$C$10, (W3 = 'Points-Table'!$A$11), 'Points-Table'!$C$11, (W3 = 'Points-Table'!$A$12), 'Points-Table'!$C$12, (W3 = 'Points-Table'!$A$13), 'Points-Table'!$C$13, true, 0 ) | Z3: =Ifs( (Y3 = 'Points-Table'!$A$4), 'Points-Table'!$C$4, (Y3 = 'Points-Table'!$A$5), 'Points-Table'!$C$5, (Y3 = 'Points-Table'!$A$6), 'Points-Table'!$C$6, (Y3 = 'Points-Table'!$A$7), 'Points-Table'!$C$7, (Y3 = 'Points-Table'!$A$8), 'Points-Table'!$C$8, (Y3 = 'Points-Table'!$A$9), 'Points-Table'!$C$9, (Y3 = 'Points-Table'!$A$10), 'Points-Table'!$C$10, (Y3 = 'Points-Table'!$A$11), 'Points-Table'!$C$11, (Y3 = 'Points-Table'!$A$12), 'Points-Table'!$C$12, (Y3 = 'Points-Table'!$A$13), 'Points-Table'!$C$13, true, 0 ) | AA3: =SUM(V3,X3,Z3) | AB3: =Ifs( ISBETWEEN(AA3, 0, 'Points-Table'!C$20, TRUE, False), 'Points-Table'!A$20, ISBETWEEN(AA3, 'Points-Table'!C$20, 'Points-Table'!C$21, TRUE, False), 'Points-Table'!A$21, ISBETWEEN(AA3, 'Points-Table'!C$22, 10000, TRUE, TRUE), 'Points-Table'!A$22, true, 0)

Sheet Mobile App - Dev
A1: Module Name | B1: Feature | C1: Sub-Feature | D1: Description | E1: Reference Link | F1: Assumption | G1: Queries | H1: Prototype Link | I1: What to do? | J1: How to do? | K1: Complexity | L1: Priority | M1: Frequency | N1: Design Available | O1: Required Development | P1: NPM Packages | Q1: Wireframes Story Points | R1: =SUM(R2:R1006) | S1: Visual Design Story Points | T1: =SUM(T2:T1006) | U1: Frontend Story Points | V1: =SUM(V2:V1006) | W1: Integration Story Points | X1: =SUM(X2:X1006) | Y1: Backend Story Points | Z1: =SUM(Z2:Z1006) | AA1: =SUM(AA2:AA1006) | AB1: T-Shirt Size | AC1: Tags | AD1: Screen Patterns | AE1: Feature Categories
A2: Project Set up | K2: Simple | L2: Must Have | Q2: 0 | R2: =Ifs( (Q2 = 'Points-Table'!$A$4), 'Points-Table'!$C$4, (Q2 = 'Points-Table'!$A$5), 'Points-Table'!$C$5, (Q2 = 'Points-Table'!$A$6), 'Points-Table'!$C$6, (Q2 = 'Points-Table'!$A$7), 'Points-Table'!$C$7, (Q2 = 'Points-Table'!$A$8), 'Points-Table'!$C$8, (Q2 = 'Points-Table'!$A$9), 'Points-Table'!$C$9, (Q2 = 'Points-Table'!$A$10), 'Points-Table'!$C$10, (Q2 = 'Points-Table'!$A$11), 'Points-Table'!$C$11, (Q2 = 'Points-Table'!$A$12), 'Points-Table'!$C$12, (Q2 = 'Points-Table'!$A$13), 'Points-Table'!$C$13, true, 0 ) | S2: 0 | T2: =Ifs( (S2 = 'Points-Table'!$A$4), 'Points-Table'!$C$4, (S2 = 'Points-Table'!$A$5), 'Points-Table'!$C$5, (S2 = 'Points-Table'!$A$6), 'Points-Table'!$C$6, (S2 = 'Points-Table'!$A$7), 'Points-Table'!$C$7, (S2 = 'Points-Table'!$A$8), 'Points-Table'!$C$8, (S2 = 'Points-Table'!$A$9), 'Points-Table'!$C$9, (S2 = 'Points-Table'!$A$10), 'Points-Table'!$C$10, (S2 = 'Points-Table'!$A$11), 'Points-Table'!$C$11, (S2 = 'Points-Table'!$A$12), 'Points-Table'!$C$12, (S2 = 'Points-Table'!$A$13), 'Points-Table'!$C$13, true, 0 ) | U2: 21 | V2: =Ifs( (U2 = 'Points-Table'!$A$4), 'Points-Table'!$C$4, (U2 = 'Points-Table'!$A$5), 'Points-Table'!$C$5, (U2 = 'Points-Table'!$A$6), 'Points-Table'!$C$6, (U2 = 'Points-Table'!$A$7), 'Points-Table'!$C$7, (U2 = 'Points-Table'!$A$8), 'Points-Table'!$C$8, (U2 = 'Points-Table'!$A$9), 'Points-Table'!$C$9, (U2 = 'Points-Table'!$A$10), 'Points-Table'!$C$10, (U2 = 'Points-Table'!$A$11), 'Points-Table'!$C$11, (U2 = 'Points-Table'!$A$12), 'Points-Table'!$C$12, (U2 = 'Points-Table'!$A$13), 'Points-Table'!$C$13, true, 0 ) | W2: 0 | X2: =Ifs( (W2 = 'Points-Table'!$A$4), 'Points-Table'!$C$4, (W2 = 'Points-Table'!$A$5), 'Points-Table'!$C$5, (W2 = 'Points-Table'!$A$6), 'Points-Table'!$C$6, (W2 = 'Points-Table'!$A$7), 'Points-Table'!$C$7, (W2 = 'Points-Table'!$A$8), 'Points-Table'!$C$8, (W2 = 'Points-Table'!$A$9), 'Points-Table'!$C$9, (W2 = 'Points-Table'!$A$10), 'Points-Table'!$C$10, (W2 = 'Points-Table'!$A$11), 'Points-Table'!$C$11, (W2 = 'Points-Table'!$A$12), 'Points-Table'!$C$12, (W2 = 'Points-Table'!$A$13), 'Points-Table'!$C$13, true, 0 ) | Y2: 0 | Z2: =Ifs( (Y2 = 'Points-Table'!$A$4), 'Points-Table'!$C$4, (Y2 = 'Points-Table'!$A$5), 'Points-Table'!$C$5, (Y2 = 'Points-Table'!$A$6), 'Points-Table'!$C$6, (Y2 = 'Points-Table'!$A$7), 'Points-Table'!$C$7, (Y2 = 'Points-Table'!$A$8), 'Points-Table'!$C$8, (Y2 = 'Points-Table'!$A$9), 'Points-Table'!$C$9, (Y2 = 'Points-Table'!$A$10), 'Points-Table'!$C$10, (Y2 = 'Points-Table'!$A$11), 'Points-Table'!$C$11, (Y2 = 'Points-Table'!$A$12), 'Points-Table'!$C$12, (Y2 = 'Points-Table'!$A$13), 'Points-Table'!$C$13, true, 0 ) | AA2: =SUM(V2,X2,Z2) | AB2: =Ifs( ISBETWEEN(AA2, 0, 'Points-Table'!C$20, TRUE, False), 'Points-Table'!A$20, ISBETWEEN(AA2, 'Points-Table'!C$20, 'Points-Table'!C$21, TRUE, False), 'Points-Table'!A$21, ISBETWEEN(AA2, 'Points-Table'!C$22, 10000, TRUE, TRUE), 'Points-Table'!A$22, true, 0)
A3: Splash screen | K3: Simple | L3: Must Have | Q3: 0 | R3: =Ifs( (Q3 = 'Points-Table'!$A$4), 'Points-Table'!$C$4, (Q3 = 'Points-Table'!$A$5), 'Points-Table'!$C$5, (Q3 = 'Points-Table'!$A$6), 'Points-Table'!$C$6, (Q3 = 'Points-Table'!$A$7), 'Points-Table'!$C$7, (Q3 = 'Points-Table'!$A$8), 'Points-Table'!$C$8, (Q3 = 'Points-Table'!$A$9), 'Points-Table'!$C$9, (Q3 = 'Points-Table'!$A$10), 'Points-Table'!$C$10, (Q3 = 'Points-Table'!$A$11), 'Points-Table'!$C$11, (Q3 = 'Points-Table'!$A$12), 'Points-Table'!$C$12, (Q3 = 'Points-Table'!$A$13), 'Points-Table'!$C$13, true, 0 ) | S3: 0 | T3: =Ifs( (S3 = 'Points-Table'!$A$4), 'Points-Table'!$C$4, (S3 = 'Points-Table'!$A$5), 'Points-Table'!$C$5, (S3 = 'Points-Table'!$A$6), 'Points-Table'!$C$6, (S3 = 'Points-Table'!$A$7), 'Points-Table'!$C$7, (S3 = 'Points-Table'!$A$8), 'Points-Table'!$C$8, (S3 = 'Points-Table'!$A$9), 'Points-Table'!$C$9, (S3 = 'Points-Table'!$A$10), 'Points-Table'!$C$10, (S3 = 'Points-Table'!$A$11), 'Points-Table'!$C$11, (S3 = 'Points-Table'!$A$12), 'Points-Table'!$C$12, (S3 = 'Points-Table'!$A$13), 'Points-Table'!$C$13, true, 0 ) | U3: 8 | V3: =Ifs( (U3 = 'Points-Table'!$A$4), 'Points-Table'!$C$4, (U3 = 'Points-Table'!$A$5), 'Points-Table'!$C$5, (U3 = 'Points-Table'!$A$6), 'Points-Table'!$C$6, (U3 = 'Points-Table'!$A$7), 'Points-Table'!$C$7, (U3 = 'Points-Table'!$A$8), 'Points-Table'!$C$8, (U3 = 'Points-Table'!$A$9), 'Points-Table'!$C$9, (U3 = 'Points-Table'!$A$10), 'Points-Table'!$C$10, (U3 = 'Points-Table'!$A$11), 'Points-Table'!$C$11, (U3 = 'Points-Table'!$A$12), 'Points-Table'!$C$12, (U3 = 'Points-Table'!$A$13), 'Points-Table'!$C$13, true, 0 ) | W3: 3 | X3: =Ifs( (W3 = 'Points-Table'!$A$4), 'Points-Table'!$C$4, (W3 = 'Points-Table'!$A$5), 'Points-Table'!$C$5, (W3 = 'Points-Table'!$A$6), 'Points-Table'!$C$6, (W3 = 'Points-Table'!$A$7), 'Points-Table'!$C$7, (W3 = 'Points-Table'!$A$8), 'Points-Table'!$C$8, (W3 = 'Points-Table'!$A$9), 'Points-Table'!$C$9, (W3 = 'Points-Table'!$A$10), 'Points-Table'!$C$10, (W3 = 'Points-Table'!$A$11), 'Points-Table'!$C$11, (W3 = 'Points-Table'!$A$12), 'Points-Table'!$C$12, (W3 = 'Points-Table'!$A$13), 'Points-Table'!$C$13, true, 0 ) | Y3: 0 | Z3: =Ifs( (Y3 = 'Points-Table'!$A$4), 'Points-Table'!$C$4, (Y3 = 'Points-Table'!$A$5), 'Points-Table'!$C$5, (Y3 = 'Points-Table'!$A$6), 'Points-Table'!$C$6, (Y3 = 'Points-Table'!$A$7), 'Points-Table'!$C$7, (Y3 = 'Points-Table'!$A$8), 'Points-Table'!$C$8, (Y3 = 'Points-Table'!$A$9), 'Points-Table'!$C$9, (Y3 = 'Points-Table'!$A$10), 'Points-Table'!$C$10, (Y3 = 'Points-Table'!$A$11), 'Points-Table'!$C$11, (Y3 = 'Points-Table'!$A$12), 'Points-Table'!$C$12, (Y3 = 'Points-Table'!$A$13), 'Points-Table'!$C$13, true, 0 ) | AA3: =SUM(V3,X3,Z3) | AB3: =Ifs( ISBETWEEN(AA3, 0, 'Points-Table'!C$20, TRUE, False), 'Points-Table'!A$20, ISBETWEEN(AA3, 'Points-Table'!C$20, 'Points-Table'!C$21, TRUE, False), 'Points-Table'!A$21, ISBETWEEN(AA3, 'Points-Table'!C$22, 10000, TRUE, TRUE), 'Points-Table'!A$22, true, 0)
A4: Onboarding screens | D4: 3 screens with embedded images about the product | K4: Simple | L4: Must Have | Q4: 0 | R4: =Ifs( (Q4 = 'Points-Table'!$A$4), 'Points-Table'!$C$4, (Q4 = 'Points-Table'!$A$5), 'Points-Table'!$C$5, (Q4 = 'Points-Table'!$A$6), 'Points-Table'!$C$6, (Q4 = 'Points-Table'!$A$7), 'Points-Table'!$C$7, (Q4 = 'Points-Table'!$A$8), 'Points-Table'!$C$8, (Q4 = 'Points-Table'!$A$9), 'Points-Table'!$C$9, (Q4 = 'Points-Table'!$A$10), 'Points-Table'!$C$10, (Q4 = 'Points-Table'!$A$11), 'Points-Table'!$C$11, (Q4 = 'Points-Table'!$A$12), 'Points-Table'!$C$12, (Q4 = 'Points-Table'!$A$13), 'Points-Table'!$C$13, true, 0 ) | S4: 0 | T4: =Ifs( (S4 = 'Points-Table'!$A$4), 'Points-Table'!$C$4, (S4 = 'Points-Table'!$A$5), 'Points-Table'!$C$5, (S4 = 'Points-Table'!$A$6), 'Points-Table'!$C$6, (S4 = 'Points-Table'!$A$7), 'Points-Table'!$C$7, (S4 = 'Points-Table'!$A$8), 'Points-Table'!$C$8, (S4 = 'Points-Table'!$A$9), 'Points-Table'!$C$9, (S4 = 'Points-Table'!$A$10), 'Points-Table'!$C$10, (S4 = 'Points-Table'!$A$11), 'Points-Table'!$C$11, (S4 = 'Points-Table'!$A$12), 'Points-Table'!$C$12, (S4 = 'Points-Table'!$A$13), 'Points-Table'!$C$13, true, 0 ) | U4: 5 | V4: =Ifs( (U4 = 'Points-Table'!$A$4), 'Points-Table'!$C$4, (U4 = 'Points-Table'!$A$5), 'Points-Table'!$C$5, (U4 = 'Points-Table'!$A$6), 'Points-Table'!$C$6, (U4 = 'Points-Table'!$A$7), 'Points-Table'!$C$7, (U4 = 'Points-Table'!$A$8), 'Points-Table'!$C$8, (U4 = 'Points-Table'!$A$9), 'Points-Table'!$C$9, (U4 = 'Points-Table'!$A$10), 'Points-Table'!$C$10, (U4 = 'Points-Table'!$A$11), 'Points-Table'!$C$11, (U4 = 'Points-Table'!$A$12), 'Points-Table'!$C$12, (U4 = 'Points-Table'!$A$13), 'Points-Table'!$C$13, true, 0 ) | W4: 0 | X4: =Ifs( (W4 = 'Points-Table'!$A$4), 'Points-Table'!$C$4, (W4 = 'Points-Table'!$A$5), 'Points-Table'!$C$5, (W4 = 'Points-Table'!$A$6), 'Points-Table'!$C$6, (W4 = 'Points-Table'!$A$7), 'Points-Table'!$C$7, (W4 = 'Points-Table'!$A$8), 'Points-Table'!$C$8, (W4 = 'Points-Table'!$A$9), 'Points-Table'!$C$9, (W4 = 'Points-Table'!$A$10), 'Points-Table'!$C$10, (W4 = 'Points-Table'!$A$11), 'Points-Table'!$C$11, (W4 = 'Points-Table'!$A$12), 'Points-Table'!$C$12, (W4 = 'Points-Table'!$A$13), 'Points-Table'!$C$13, true, 0 ) | Y4: 0 | Z4: =Ifs( (Y4 = 'Points-Table'!$A$4), 'Points-Table'!$C$4, (Y4 = 'Points-Table'!$A$5), 'Points-Table'!$C$5, (Y4 = 'Points-Table'!$A$6), 'Points-Table'!$C$6, (Y4 = 'Points-Table'!$A$7), 'Points-Table'!$C$7, (Y4 = 'Points-Table'!$A$8), 'Points-Table'!$C$8, (Y4 = 'Points-Table'!$A$9), 'Points-Table'!$C$9, (Y4 = 'Points-Table'!$A$10), 'Points-Table'!$C$10, (Y4 = 'Points-Table'!$A$11), 'Points-Table'!$C$11, (Y4 = 'Points-Table'!$A$12), 'Points-Table'!$C$12, (Y4 = 'Points-Table'!$A$13), 'Points-Table'!$C$13, true, 0 ) | AA4: =SUM(V4,X4,Z4) | AB4: =Ifs( ISBETWEEN(AA4, 0, 'Points-Table'!C$20, TRUE, False), 'Points-Table'!A$20, ISBETWEEN(AA4, 'Points-Table'!C$20, 'Points-Table'!C$21, TRUE, False), 'Points-Table'!A$21, ISBETWEEN(AA4, 'Points-Table'!C$22, 10000, TRUE, TRUE), 'Points-Table'!A$22, true, 0)
A5: Registration and Login | B5: Login | C5: Phone | F5: We will be using the existing login flow built for web app, Flag for identifying if MPIN/biometric setup is done or not will be added in this API. | K5: Simple | L5: Must Have | Q5: 0 | R5: =Ifs( (Q5 = 'Points-Table'!$A$4), 'Points-Table'!$C$4, (Q5 = 'Points-Table'!$A$5), 'Points-Table'!$C$5, (Q5 = 'Points-Table'!$A$6), 'Points-Table'!$C$6, (Q5 = 'Points-Table'!$A$7), 'Points-Table'!$C$7, (Q5 = 'Points-Table'!$A$8), 'Points-Table'!$C$8, (Q5 = 'Points-Table'!$A$9), 'Points-Table'!$C$9, (Q5 = 'Points-Table'!$A$10), 'Points-Table'!$C$10, (Q5 = 'Points-Table'!$A$11), 'Points-Table'!$C$11, (Q5 = 'Points-Table'!$A$12), 'Points-Table'!$C$12, (Q5 = 'Points-Table'!$A$13), 'Points-Table'!$C$13, true, 0 ) | S5: 0 | T5: =Ifs( (S5 = 'Points-Table'!$A$4), 'Points-Table'!$C$4, (S5 = 'Points-Table'!$A$5), 'Points-Table'!$C$5, (S5 = 'Points-Table'!$A$6), 'Points-Table'!$C$6, (S5 = 'Points-Table'!$A$7), 'Points-Table'!$C$7, (S5 = 'Points-Table'!$A$8), 'Points-Table'!$C$8, (S5 = 'Points-Table'!$A$9), 'Points-Table'!$C$9, (S5 = 'Points-Table'!$A$10), 'Points-Table'!$C$10, (S5 = 'Points-Table'!$A$11), 'Points-Table'!$C$11, (S5 = 'Points-Table'!$A$12), 'Points-Table'!$C$12, (S5 = 'Points-Table'!$A$13), 'Points-Table'!$C$13, true, 0 ) | U5: 5 | V5: =Ifs( (U5 = 'Points-Table'!$A$4), 'Points-Table'!$C$4, (U5 = 'Points-Table'!$A$5), 'Points-Table'!$C$5, (U5 = 'Points-Table'!$A$6), 'Points-Table'!$C$6, (U5 = 'Points-Table'!$A$7), 'Points-Table'!$C$7, (U5 = 'Points-Table'!$A$8), 'Points-Table'!$C$8, (U5 = 'Points-Table'!$A$9), 'Points-Table'!$C$9, (U5 = 'Points-Table'!$A$10), 'Points-Table'!$C$10, (U5 = 'Points-Table'!$A$11), 'Points-Table'!$C$11, (U5 = 'Points-Table'!$A$12), 'Points-Table'!$C$12, (U5 = 'Points-Table'!$A$13), 'Points-Table'!$C$13, true, 0 ) | W5: 3 | X5: =Ifs( (W5 = 'Points-Table'!$A$4), 'Points-Table'!$C$4, (W5 = 'Points-Table'!$A$5), 'Points-Table'!$C$5, (W5 = 'Points-Table'!$A$6), 'Points-Table'!$C$6, (W5 = 'Points-Table'!$A$7), 'Points-Table'!$C$7, (W5 = 'Points-Table'!$A$8), 'Points-Table'!$C$8, (W5 = 'Points-Table'!$A$9), 'Points-Table'!$C$9, (W5 = 'Points-Table'!$A$10), 'Points-Table'!$C$10, (W5 = 'Points-Table'!$A$11), 'Points-Table'!$C$11, (W5 = 'Points-Table'!$A$12), 'Points-Table'!$C$12, (W5 = 'Points-Table'!$A$13), 'Points-Table'!$C$13, true, 0 ) | Y5: 0 | Z5: =Ifs( (Y5 = 'Points-Table'!$A$4), 'Points-Table'!$C$4, (Y5 = 'Points-Table'!$A$5), 'Points-Table'!$C$5, (Y5 = 'Points-Table'!$A$6), 'Points-Table'!$C$6, (Y5 = 'Points-Table'!$A$7), 'Points-Table'!$C$7, (Y5 = 'Points-Table'!$A$8), 'Points-Table'!$C$8, (Y5 = 'Points-Table'!$A$9), 'Points-Table'!$C$9, (Y5 = 'Points-Table'!$A$10), 'Points-Table'!$C$10, (Y5 = 'Points-Table'!$A$11), 'Points-Table'!$C$11, (Y5 = 'Points-Table'!$A$12), 'Points-Table'!$C$12, (Y5 = 'Points-Table'!$A$13), 'Points-Table'!$C$13, true, 0 ) | AA5: =SUM(V5,X5,Z5) | AB5: =Ifs( ISBETWEEN(AA5, 0, 'Points-Table'!C$20, TRUE, False), 'Points-Table'!A$20, ISBETWEEN(AA5, 'Points-Table'!C$20, 'Points-Table'!C$21, TRUE, False), 'Points-Table'!A$21, ISBETWEEN(AA5, 'Points-Table'!C$22, 10000, TRUE, TRUE), 'Points-Table'!A$22, true, 0)
A6: Registration and Login | B6: Login | C6: OTP auth | K6: Simple | L6: Must Have | Q6: 0 | R6: =Ifs( (Q6 = 'Points-Table'!$A$4), 'Points-Table'!$C$4, (Q6 = 'Points-Table'!$A$5), 'Points-Table'!$C$5, (Q6 = 'Points-Table'!$A$6), 'Points-Table'!$C$6, (Q6 = 'Points-Table'!$A$7), 'Points-Table'!$C$7, (Q6 = 'Points-Table'!$A$8), 'Points-Table'!$C$8, (Q6 = 'Points-Table'!$A$9), 'Points-Table'!$C$9, (Q6 = 'Points-Table'!$A$10), 'Points-Table'!$C$10, (Q6 = 'Points-Table'!$A$11), 'Points-Table'!$C$11, (Q6 = 'Points-Table'!$A$12), 'Points-Table'!$C$12, (Q6 = 'Points-Table'!$A$13), 'Points-Table'!$C$13, true, 0 ) | S6: 0 | T6: =Ifs( (S6 = 'Points-Table'!$A$4), 'Points-Table'!$C$4, (S6 = 'Points-Table'!$A$5), 'Points-Table'!$C$5, (S6 = 'Points-Table'!$A$6), 'Points-Table'!$C$6, (S6 = 'Points-Table'!$A$7), 'Points-Table'!$C$7, (S6 = 'Points-Table'!$A$8), 'Points-Table'!$C$8, (S6 = 'Points-Table'!$A$9), 'Points-Table'!$C$9, (S6 = 'Points-Table'!$A$10), 'Points-Table'!$C$10, (S6 = 'Points-Table'!$A$11), 'Points-Table'!$C$11, (S6 = 'Points-Table'!$A$12), 'Points-Table'!$C$12, (S6 = 'Points-Table'!$A$13), 'Points-Table'!$C$13, true, 0 ) | U6: 5 | V6: =Ifs( (U6 = 'Points-Table'!$A$4), 'Points-Table'!$C$4, (U6 = 'Points-Table'!$A$5), 'Points-Table'!$C$5, (U6 = 'Points-Table'!$A$6), 'Points-Table'!$C$6, (U6 = 'Points-Table'!$A$7), 'Points-Table'!$C$7, (U6 = 'Points-Table'!$A$8), 'Points-Table'!$C$8, (U6 = 'Points-Table'!$A$9), 'Points-Table'!$C$9, (U6 = 'Points-Table'!$A$10), 'Points-Table'!$C$10, (U6 = 'Points-Table'!$A$11), 'Points-Table'!$C$11, (U6 = 'Points-Table'!$A$12), 'Points-Table'!$C$12, (U6 = 'Points-Table'!$A$13), 'Points-Table'!$C$13, true, 0 ) | W6: 3 | X6: =Ifs( (W6 = 'Points-Table'!$A$4), 'Points-Table'!$C$4, (W6 = 'Points-Table'!$A$5), 'Points-Table'!$C$5, (W6 = 'Points-Table'!$A$6), 'Points-Table'!$C$6, (W6 = 'Points-Table'!$A$7), 'Points-Table'!$C$7, (W6 = 'Points-Table'!$A$8), 'Points-Table'!$C$8, (W6 = 'Points-Table'!$A$9), 'Points-Table'!$C$9, (W6 = 'Points-Table'!$A$10), 'Points-Table'!$C$10, (W6 = 'Points-Table'!$A$11), 'Points-Table'!$C$11, (W6 = 'Points-Table'!$A$12), 'Points-Table'!$C$12, (W6 = 'Points-Table'!$A$13), 'Points-Table'!$C$13, true, 0 ) | Y6: 0 | Z6: =Ifs( (Y6 = 'Points-Table'!$A$4), 'Points-Table'!$C$4, (Y6 = 'Points-Table'!$A$5), 'Points-Table'!$C$5, (Y6 = 'Points-Table'!$A$6), 'Points-Table'!$C$6, (Y6 = 'Points-Table'!$A$7), 'Points-Table'!$C$7, (Y6 = 'Points-Table'!$A$8), 'Points-Table'!$C$8, (Y6 = 'Points-Table'!$A$9), 'Points-Table'!$C$9, (Y6 = 'Points-Table'!$A$10), 'Points-Table'!$C$10, (Y6 = 'Points-Table'!$A$11), 'Points-Table'!$C$11, (Y6 = 'Points-Table'!$A$12), 'Points-Table'!$C$12, (Y6 = 'Points-Table'!$A$13), 'Points-Table'!$C$13, true, 0 ) | AA6: =SUM(V6,X6,Z6) | AB6: =Ifs( ISBETWEEN(AA6, 0, 'Points-Table'!C$20, TRUE, False), 'Points-Table'!A$20, ISBETWEEN(AA6, 'Points-Table'!C$20, 'Points-Table'!C$21, TRUE, False), 'Points-Table'!A$21, ISBETWEEN(AA6, 'Points-Table'!C$22, 10000, TRUE, TRUE), 'Points-Table'!A$22, true, 0)
A7: Registration and Login | B7: Login | C7: MPIN auth | K7: Simple | L7: Must Have | Q7: 0 | R7: =Ifs( (Q7 = 'Points-Table'!$A$4), 'Points-Table'!$C$4, (Q7 = 'Points-Table'!$A$5), 'Points-Table'!$C$5, (Q7 = 'Points-Table'!$A$6), 'Points-Table'!$C$6, (Q7 = 'Points-Table'!$A$7), 'Points-Table'!$C$7, (Q7 = 'Points-Table'!$A$8), 'Points-Table'!$C$8, (Q7 = 'Points-Table'!$A$9), 'Points-Table'!$C$9, (Q7 = 'Points-Table'!$A$10), 'Points-Table'!$C$10, (Q7 = 'Points-Table'!$A$11), 'Points-Table'!$C$11, (Q7 = 'Points-Table'!$A$12), 'Points-Table'!$C$12, (Q7 = 'Points-Table'!$A$13), 'Points-Table'!$C$13, true, 0 ) | S7: 0 | T7: =Ifs( (S7 = 'Points-Table'!$A$4), 'Points-Table'!$C$4, (S7 = 'Points-Table'!$A$5), 'Points-Table'!$C$5, (S7 = 'Points-Table'!$A$6), 'Points-Table'!$C$6, (S7 = 'Points-Table'!$A$7), 'Points-Table'!$C$7, (S7 = 'Points-Table'!$A$8), 'Points-Table'!$C$8, (S7 = 'Points-Table'!$A$9), 'Points-Table'!$C$9, (S7 = 'Points-Table'!$A$10), 'Points-Table'!$C$10, (S7 = 'Points-Table'!$A$11), 'Points-Table'!$C$11, (S7 = 'Points-Table'!$A$12), 'Points-Table'!$C$12, (S7 = 'Points-Table'!$A$13), 'Points-Table'!$C$13, true, 0 ) | U7: 5 | V7: =Ifs( (U7 = 'Points-Table'!$A$4), 'Points-Table'!$C$4, (U7 = 'Points-Table'!$A$5), 'Points-Table'!$C$5, (U7 = 'Points-Table'!$A$6), 'Points-Table'!$C$6, (U7 = 'Points-Table'!$A$7), 'Points-Table'!$C$7, (U7 = 'Points-Table'!$A$8), 'Points-Table'!$C$8, (U7 = 'Points-Table'!$A$9), 'Points-Table'!$C$9, (U7 = 'Points-Table'!$A$10), 'Points-Table'!$C$10, (U7 = 'Points-Table'!$A$11), 'Points-Table'!$C$11, (U7 = 'Points-Table'!$A$12), 'Points-Table'!$C$12, (U7 = 'Points-Table'!$A$13), 'Points-Table'!$C$13, true, 0 ) | W7: 3 | X7: =Ifs( (W7 = 'Points-Table'!$A$4), 'Points-Table'!$C$4, (W7 = 'Points-Table'!$A$5), 'Points-Table'!$C$5, (W7 = 'Points-Table'!$A$6), 'Points-Table'!$C$6, (W7 = 'Points-Table'!$A$7), 'Points-Table'!$C$7, (W7 = 'Points-Table'!$A$8), 'Points-Table'!$C$8, (W7 = 'Points-Table'!$A$9), 'Points-Table'!$C$9, (W7 = 'Points-Table'!$A$10), 'Points-Table'!$C$10, (W7 = 'Points-Table'!$A$11), 'Points-Table'!$C$11, (W7 = 'Points-Table'!$A$12), 'Points-Table'!$C$12, (W7 = 'Points-Table'!$A$13), 'Points-Table'!$C$13, true, 0 ) | Y7: 0 | Z7: =Ifs( (Y7 = 'Points-Table'!$A$4), 'Points-Table'!$C$4, (Y7 = 'Points-Table'!$A$5), 'Points-Table'!$C$5, (Y7 = 'Points-Table'!$A$6), 'Points-Table'!$C$6, (Y7 = 'Points-Table'!$A$7), 'Points-Table'!$C$7, (Y7 = 'Points-Table'!$A$8), 'Points-Table'!$C$8, (Y7 = 'Points-Table'!$A$9), 'Points-Table'!$C$9, (Y7 = 'Points-Table'!$A$10), 'Points-Table'!$C$10, (Y7 = 'Points-Table'!$A$11), 'Points-Table'!$C$11, (Y7 = 'Points-Table'!$A$12), 'Points-Table'!$C$12, (Y7 = 'Points-Table'!$A$13), 'Points-Table'!$C$13, true, 0 ) | AA7: =SUM(V7,X7,Z7) | AB7: =Ifs( ISBETWEEN(AA7, 0, 'Points-Table'!C$20, TRUE, False), 'Points-Table'!A$20, ISBETWEEN(AA7, 'Points-Table'!C$20, 'Points-Table'!C$21, TRUE, False), 'Points-Table'!A$21, ISBETWEEN(AA7, 'Points-Table'!C$22, 10000, TRUE, TRUE), 'Points-Table'!A$22, true, 0)
A8: Registration and Login | B8: Login | C8: Forgot MPIN | K8: Simple | L8: Must Have | Q8: 0 | R8: =Ifs( (Q8 = 'Points-Table'!$A$4), 'Points-Table'!$C$4, (Q8 = 'Points-Table'!$A$5), 'Points-Table'!$C$5, (Q8 = 'Points-Table'!$A$6), 'Points-Table'!$C$6, (Q8 = 'Points-Table'!$A$7), 'Points-Table'!$C$7, (Q8 = 'Points-Table'!$A$8), 'Points-Table'!$C$8, (Q8 = 'Points-Table'!$A$9), 'Points-Table'!$C$9, (Q8 = 'Points-Table'!$A$10), 'Points-Table'!$C$10, (Q8 = 'Points-Table'!$A$11), 'Points-Table'!$C$11, (Q8 = 'Points-Table'!$A$12), 'Points-Table'!$C$12, (Q8 = 'Points-Table'!$A$13), 'Points-Table'!$C$13, true, 0 ) | S8: 0 | T8: =Ifs( (S8 = 'Points-Table'!$A$4), 'Points-Table'!$C$4, (S8 = 'Points-Table'!$A$5), 'Points-Table'!$C$5, (S8 = 'Points-Table'!$A$6), 'Points-Table'!$C$6, (S8 = 'Points-Table'!$A$7), 'Points-Table'!$C$7, (S8 = 'Points-Table'!$A$8), 'Points-Table'!$C$8, (S8 = 'Points-Table'!$A$9), 'Points-Table'!$C$9, (S8 = 'Points-Table'!$A$10), 'Points-Table'!$C$10, (S8 = 'Points-Table'!$A$11), 'Points-Table'!$C$11, (S8 = 'Points-Table'!$A$12), 'Points-Table'!$C$12, (S8 = 'Points-Table'!$A$13), 'Points-Table'!$C$13, true, 0 ) | U8: 5 | V8: =Ifs( (U8 = 'Points-Table'!$A$4), 'Points-Table'!$C$4, (U8 = 'Points-Table'!$A$5), 'Points-Table'!$C$5, (U8 = 'Points-Table'!$A$6), 'Points-Table'!$C$6, (U8 = 'Points-Table'!$A$7), 'Points-Table'!$C$7, (U8 = 'Points-Table'!$A$8), 'Points-Table'!$C$8, (U8 = 'Points-Table'!$A$9), 'Points-Table'!$C$9, (U8 = 'Points-Table'!$A$10), 'Points-Table'!$C$10, (U8 = 'Points-Table'!$A$11), 'Points-Table'!$C$11, (U8 = 'Points-Table'!$A$12), 'Points-Table'!$C$12, (U8 = 'Points-Table'!$A$13), 'Points-Table'!$C$13, true, 0 ) | W8: 3 | X8: =Ifs( (W8 = 'Points-Table'!$A$4), 'Points-Table'!$C$4, (W8 = 'Points-Table'!$A$5), 'Points-Table'!$C$5, (W8 = 'Points-Table'!$A$6), 'Points-Table'!$C$6, (W8 = 'Points-Table'!$A$7), 'Points-Table'!$C$7, (W8 = 'Points-Table'!$A$8), 'Points-Table'!$C$8, (W8 = 'Points-Table'!$A$9), 'Points-Table'!$C$9, (W8 = 'Points-Table'!$A$10), 'Points-Table'!$C$10, (W8 = 'Points-Table'!$A$11), 'Points-Table'!$C$11, (W8 = 'Points-Table'!$A$12), 'Points-Table'!$C$12, (W8 = 'Points-Table'!$A$13), 'Points-Table'!$C$13, true, 0 ) | Y8: 0 | Z8: =Ifs( (Y8 = 'Points-Table'!$A$4), 'Points-Table'!$C$4, (Y8 = 'Points-Table'!$A$5), 'Points-Table'!$C$5, (Y8 = 'Points-Table'!$A$6), 'Points-Table'!$C$6, (Y8 = 'Points-Table'!$A$7), 'Points-Table'!$C$7, (Y8 = 'Points-Table'!$A$8), 'Points-Table'!$C$8, (Y8 = 'Points-Table'!$A$9), 'Points-Table'!$C$9, (Y8 = 'Points-Table'!$A$10), 'Points-Table'!$C$10, (Y8 = 'Points-Table'!$A$11), 'Points-Table'!$C$11, (Y8 = 'Points-Table'!$A$12), 'Points-Table'!$C$12, (Y8 = 'Points-Table'!$A$13), 'Points-Table'!$C$13, true, 0 ) | AA8: =SUM(V8,X8,Z8) | AB8: =Ifs( ISBETWEEN(AA8, 0, 'Points-Table'!C$20, TRUE, False), 'Points-Table'!A$20, ISBETWEEN(AA8, 'Points-Table'!C$20, 'Points-Table'!C$21, TRUE, False), 'Points-Table'!A$21, ISBETWEEN(AA8, 'Points-Table'!C$22, 10000, TRUE, TRUE), 'Points-Table'!A$22, true, 0)
A9: Registration and Login | B9: Login | C9: Social Login | D9: Google and Facebook | F9: We will be using the existing login flow built for web app, firebase config will be provided by rajshree team, Rajshree team will help in setting up facebook SDK & google developer account needed for social signin. | K9: Simple | L9: Must Have | Q9: 0 | R9: =Ifs( (Q9 = 'Points-Table'!$A$4), 'Points-Table'!$C$4, (Q9 = 'Points-Table'!$A$5), 'Points-Table'!$C$5, (Q9 = 'Points-Table'!$A$6), 'Points-Table'!$C$6, (Q9 = 'Points-Table'!$A$7), 'Points-Table'!$C$7, (Q9 = 'Points-Table'!$A$8), 'Points-Table'!$C$8, (Q9 = 'Points-Table'!$A$9), 'Points-Table'!$C$9, (Q9 = 'Points-Table'!$A$10), 'Points-Table'!$C$10, (Q9 = 'Points-Table'!$A$11), 'Points-Table'!$C$11, (Q9 = 'Points-Table'!$A$12), 'Points-Table'!$C$12, (Q9 = 'Points-Table'!$A$13), 'Points-Table'!$C$13, true, 0 ) | S9: 0 | T9: =Ifs( (S9 = 'Points-Table'!$A$4), 'Points-Table'!$C$4, (S9 = 'Points-Table'!$A$5), 'Points-Table'!$C$5, (S9 = 'Points-Table'!$A$6), 'Points-Table'!$C$6, (S9 = 'Points-Table'!$A$7), 'Points-Table'!$C$7, (S9 = 'Points-Table'!$A$8), 'Points-Table'!$C$8, (S9 = 'Points-Table'!$A$9), 'Points-Table'!$C$9, (S9 = 'Points-Table'!$A$10), 'Points-Table'!$C$10, (S9 = 'Points-Table'!$A$11), 'Points-Table'!$C$11, (S9 = 'Points-Table'!$A$12), 'Points-Table'!$C$12, (S9 = 'Points-Table'!$A$13), 'Points-Table'!$C$13, true, 0 ) | U9: 3 | V9: =Ifs( (U9 = 'Points-Table'!$A$4), 'Points-Table'!$C$4, (U9 = 'Points-Table'!$A$5), 'Points-Table'!$C$5, (U9 = 'Points-Table'!$A$6), 'Points-Table'!$C$6, (U9 = 'Points-Table'!$A$7), 'Points-Table'!$C$7, (U9 = 'Points-Table'!$A$8), 'Points-Table'!$C$8, (U9 = 'Points-Table'!$A$9), 'Points-Table'!$C$9, (U9 = 'Points-Table'!$A$10), 'Points-Table'!$C$10, (U9 = 'Points-Table'!$A$11), 'Points-Table'!$C$11, (U9 = 'Points-Table'!$A$12), 'Points-Table'!$C$12, (U9 = 'Points-Table'!$A$13), 'Points-Table'!$C$13, true, 0 ) | W9: 8 | X9: =Ifs( (W9 = 'Points-Table'!$A$4), 'Points-Table'!$C$4, (W9 = 'Points-Table'!$A$5), 'Points-Table'!$C$5, (W9 = 'Points-Table'!$A$6), 'Points-Table'!$C$6, (W9 = 'Points-Table'!$A$7), 'Points-Table'!$C$7, (W9 = 'Points-Table'!$A$8), 'Points-Table'!$C$8, (W9 = 'Points-Table'!$A$9), 'Points-Table'!$C$9, (W9 = 'Points-Table'!$A$10), 'Points-Table'!$C$10, (W9 = 'Points-Table'!$A$11), 'Points-Table'!$C$11, (W9 = 'Points-Table'!$A$12), 'Points-Table'!$C$12, (W9 = 'Points-Table'!$A$13), 'Points-Table'!$C$13, true, 0 ) | Y9: 0 | Z9: =Ifs( (Y9 = 'Points-Table'!$A$4), 'Points-Table'!$C$4, (Y9 = 'Points-Table'!$A$5), 'Points-Table'!$C$5, (Y9 = 'Points-Table'!$A$6), 'Points-Table'!$C$6, (Y9 = 'Points-Table'!$A$7), 'Points-Table'!$C$7, (Y9 = 'Points-Table'!$A$8), 'Points-Table'!$C$8, (Y9 = 'Points-Table'!$A$9), 'Points-Table'!$C$9, (Y9 = 'Points-Table'!$A$10), 'Points-Table'!$C$10, (Y9 = 'Points-Table'!$A$11), 'Points-Table'!$C$11, (Y9 = 'Points-Table'!$A$12), 'Points-Table'!$C$12, (Y9 = 'Points-Table'!$A$13), 'Points-Table'!$C$13, true, 0 ) | AA9: =SUM(V9,X9,Z9) | AB9: =Ifs( ISBETWEEN(AA9, 0, 'Points-Table'!C$20, TRUE, False), 'Points-Table'!A$20, ISBETWEEN(AA9, 'Points-Table'!C$20, 'Points-Table'!C$21, TRUE, False), 'Points-Table'!A$21, ISBETWEEN(AA9, 'Points-Table'!C$22, 10000, TRUE, TRUE), 'Points-Table'!A$22, true, 0)
A10: Registration and Login | B10: Login | C10: Biometric auth | F10: We need two APIs for this one for storing biometric hash and other for validating the hash. | K10: Simple | L10: Must Have | Q10: 0 | R10: =Ifs( (Q10 = 'Points-Table'!$A$4), 'Points-Table'!$C$4, (Q10 = 'Points-Table'!$A$5), 'Points-Table'!$C$5, (Q10 = 'Points-Table'!$A$6), 'Points-Table'!$C$6, (Q10 = 'Points-Table'!$A$7), 'Points-Table'!$C$7, (Q10 = 'Points-Table'!$A$8), 'Points-Table'!$C$8, (Q10 = 'Points-Table'!$A$9), 'Points-Table'!$C$9, (Q10 = 'Points-Table'!$A$10), 'Points-Table'!$C$10, (Q10 = 'Points-Table'!$A$11), 'Points-Table'!$C$11, (Q10 = 'Points-Table'!$A$12), 'Points-Table'!$C$12, (Q10 = 'Points-Table'!$A$13), 'Points-Table'!$C$13, true, 0 ) | S10: 0 | T10: =Ifs( (S10 = 'Points-Table'!$A$4), 'Points-Table'!$C$4, (S10 = 'Points-Table'!$A$5), 'Points-Table'!$C$5, (S10 = 'Points-Table'!$A$6), 'Points-Table'!$C$6, (S10 = 'Points-Table'!$A$7), 'Points-Table'!$C$7, (S10 = 'Points-Table'!$A$8), 'Points-Table'!$C$8, (S10 = 'Points-Table'!$A$9), 'Points-Table'!$C$9, (S10 = 'Points-Table'!$A$10), 'Points-Table'!$C$10, (S10 = 'Points-Table'!$A$11), 'Points-Table'!$C$11, (S10 = 'Points-Table'!$A$12), 'Points-Table'!$C$12, (S10 = 'Points-Table'!$A$13), 'Points-Table'!$C$13, true, 0 ) | U10: 21 | V10: =Ifs( (U10 = 'Points-Table'!$A$4), 'Points-Table'!$C$4, (U10 = 'Points-Table'!$A$5), 'Points-Table'!$C$5, (U10 = 'Points-Table'!$A$6), 'Points-Table'!$C$6, (U10 = 'Points-Table'!$A$7), 'Points-Table'!$C$7, (U10 = 'Points-Table'!$A$8), 'Points-Table'!$C$8, (U10 = 'Points-Table'!$A$9), 'Points-Table'!$C$9, (U10 = 'Points-Table'!$A$10), 'Points-Table'!$C$10, (U10 = 'Points-Table'!$A$11), 'Points-Table'!$C$11, (U10 = 'Points-Table'!$A$12), 'Points-Table'!$C$12, (U10 = 'Points-Table'!$A$13), 'Points-Table'!$C$13, true, 0 ) | W10: 5 | X10: =Ifs( (W10 = 'Points-Table'!$A$4), 'Points-Table'!$C$4, (W10 = 'Points-Table'!$A$5), 'Points-Table'!$C$5, (W10 = 'Points-Table'!$A$6), 'Points-Table'!$C$6, (W10 = 'Points-Table'!$A$7), 'Points-Table'!$C$7, (W10 = 'Points-Table'!$A$8), 'Points-Table'!$C$8, (W10 = 'Points-Table'!$A$9), 'Points-Table'!$C$9, (W10 = 'Points-Table'!$A$10), 'Points-Table'!$C$10, (W10 = 'Points-Table'!$A$11), 'Points-Table'!$C$11, (W10 = 'Points-Table'!$A$12), 'Points-Table'!$C$12, (W10 = 'Points-Table'!$A$13), 'Points-Table'!$C$13, true, 0 ) | Y10: 0 | Z10: =Ifs( (Y10 = 'Points-Table'!$A$4), 'Points-Table'!$C$4, (Y10 = 'Points-Table'!$A$5), 'Points-Table'!$C$5, (Y10 = 'Points-Table'!$A$6), 'Points-Table'!$C$6, (Y10 = 'Points-Table'!$A$7), 'Points-Table'!$C$7, (Y10 = 'Points-Table'!$A$8), 'Points-Table'!$C$8, (Y10 = 'Points-Table'!$A$9), 'Points-Table'!$C$9, (Y10 = 'Points-Table'!$A$10), 'Points-Table'!$C$10, (Y10 = 'Points-Table'!$A$11), 'Points-Table'!$C$11, (Y10 = 'Points-Table'!$A$12), 'Points-Table'!$C$12, (Y10 = 'Points-Table'!$A$13), 'Points-Table'!$C$13, true, 0 ) | AA10: =SUM(V10,X10,Z10) | AB10: =Ifs( ISBETWEEN(AA10, 0, 'Points-Table'!C$20, TRUE, False), 'Points-Table'!A$20, ISBETWEEN(AA10, 'Points-Table'!C$20, 'Points-Table'!C$21, TRUE, False), 'Points-Table'!A$21, ISBETWEEN(AA10, 'Points-Table'!C$22, 10000, TRUE, TRUE), 'Points-Table'!A$22, true, 0)
A11: Registration and Login | B11: Login | C11: Disclaimer | F11: This will be shown once completion of signup flow | K11: Simple | L11: Must Have | Q11: 0 | R11: =Ifs( (Q11 = 'Points-Table'!$A$4), 'Points-Table'!$C$4, (Q11 = 'Points-Table'!$A$5), 'Points-Table'!$C$5, (Q11 = 'Points-Table'!$A$6), 'Points-Table'!$C$6, (Q11 = 'Points-Table'!$A$7), 'Points-Table'!$C$7, (Q11 = 'Points-Table'!$A$8), 'Points-Table'!$C$8, (Q11 = 'Points-Table'!$A$9), 'Points-Table'!$C$9, (Q11 = 'Points-Table'!$A$10), 'Points-Table'!$C$10, (Q11 = 'Points-Table'!$A$11), 'Points-Table'!$C$11, (Q11 = 'Points-Table'!$A$12), 'Points-Table'!$C$12, (Q11 = 'Points-Table'!$A$13), 'Points-Table'!$C$13, true, 0 ) | S11: 0 | T11: =Ifs( (S11 = 'Points-Table'!$A$4), 'Points-Table'!$C$4, (S11 = 'Points-Table'!$A$5), 'Points-Table'!$C$5, (S11 = 'Points-Table'!$A$6), 'Points-Table'!$C$6, (S11 = 'Points-Table'!$A$7), 'Points-Table'!$C$7, (S11 = 'Points-Table'!$A$8), 'Points-Table'!$C$8, (S11 = 'Points-Table'!$A$9), 'Points-Table'!$C$9, (S11 = 'Points-Table'!$A$10), 'Points-Table'!$C$10, (S11 = 'Points-Table'!$A$11), 'Points-Table'!$C$11, (S11 = 'Points-Table'!$A$12), 'Points-Table'!$C$12, (S11 = 'Points-Table'!$A$13), 'Points-Table'!$C$13, true, 0 ) | U11: 2 | V11: =Ifs( (U11 = 'Points-Table'!$A$4), 'Points-Table'!$C$4, (U11 = 'Points-Table'!$A$5), 'Points-Table'!$C$5, (U11 = 'Points-Table'!$A$6), 'Points-Table'!$C$6, (U11 = 'Points-Table'!$A$7), 'Points-Table'!$C$7, (U11 = 'Points-Table'!$A$8), 'Points-Table'!$C$8, (U11 = 'Points-Table'!$A$9), 'Points-Table'!$C$9, (U11 = 'Points-Table'!$A$10), 'Points-Table'!$C$10, (U11 = 'Points-Table'!$A$11), 'Points-Table'!$C$11, (U11 = 'Points-Table'!$A$12), 'Points-Table'!$C$12, (U11 = 'Points-Table'!$A$13), 'Points-Table'!$C$13, true, 0 ) | W11: 0 | X11: =Ifs( (W11 = 'Points-Table'!$A$4), 'Points-Table'!$C$4, (W11 = 'Points-Table'!$A$5), 'Points-Table'!$C$5, (W11 = 'Points-Table'!$A$6), 'Points-Table'!$C$6, (W11 = 'Points-Table'!$A$7), 'Points-Table'!$C$7, (W11 = 'Points-Table'!$A$8), 'Points-Table'!$C$8, (W11 = 'Points-Table'!$A$9), 'Points-Table'!$C$9, (W11 = 'Points-Table'!$A$10), 'Points-Table'!$C$10, (W11 = 'Points-Table'!$A$11), 'Points-Table'!$C$11, (W11 = 'Points-Table'!$A$12), 'Points-Table'!$C$12, (W11 = 'Points-Table'!$A$13), 'Points-Table'!$C$13, true, 0 ) | Y11: 0 | Z11: =Ifs( (Y11 = 'Points-Table'!$A$4), 'Points-Table'!$C$4, (Y11 = 'Points-Table'!$A$5), 'Points-Table'!$C$5, (Y11 = 'Points-Table'!$A$6), 'Points-Table'!$C$6, (Y11 = 'Points-Table'!$A$7), 'Points-Table'!$C$7, (Y11 = 'Points-Table'!$A$8), 'Points-Table'!$C$8, (Y11 = 'Points-Table'!$A$9), 'Points-Table'!$C$9, (Y11 = 'Points-Table'!$A$10), 'Points-Table'!$C$10, (Y11 = 'Points-Table'!$A$11), 'Points-Table'!$C$11, (Y11 = 'Points-Table'!$A$12), 'Points-Table'!$C$12, (Y11 = 'Points-Table'!$A$13), 'Points-Table'!$C$13, true, 0 ) | AA11: =SUM(V11,X11,Z11) | AB11: =Ifs( ISBETWEEN(AA11, 0, 'Points-Table'!C$20, TRUE, False), 'Points-Table'!A$20, ISBETWEEN(AA11, 'Points-Table'!C$20, 'Points-Table'!C$21, TRUE, False), 'Points-Table'!A$21, ISBETWEEN(AA11, 'Points-Table'!C$22, 10000, TRUE, TRUE), 'Points-Table'!A$22, true, 0)
A12: Guest user flow | F12: User can skip sign-in and explore other screens. Auth actions will be restricted. User will have proceed with sign in for that. | K12: Simple | L12: Must Have | Q12: 0 | R12: =Ifs( (Q12 = 'Points-Table'!$A$4), 'Points-Table'!$C$4, (Q12 = 'Points-Table'!$A$5), 'Points-Table'!$C$5, (Q12 = 'Points-Table'!$A$6), 'Points-Table'!$C$6, (Q12 = 'Points-Table'!$A$7), 'Points-Table'!$C$7, (Q12 = 'Points-Table'!$A$8), 'Points-Table'!$C$8, (Q12 = 'Points-Table'!$A$9), 'Points-Table'!$C$9, (Q12 = 'Points-Table'!$A$10), 'Points-Table'!$C$10, (Q12 = 'Points-Table'!$A$11), 'Points-Table'!$C$11, (Q12 = 'Points-Table'!$A$12), 'Points-Table'!$C$12, (Q12 = 'Points-Table'!$A$13), 'Points-Table'!$C$13, true, 0 ) | S12: 0 | T12: =Ifs( (S12 = 'Points-Table'!$A$4), 'Points-Table'!$C$4, (S12 = 'Points-Table'!$A$5), 'Points-Table'!$C$5, (S12 = 'Points-Table'!$A$6), 'Points-Table'!$C$6, (S12 = 'Points-Table'!$A$7), 'Points-Table'!$C$7, (S12 = 'Points-Table'!$A$8), 'Points-Table'!$C$8, (S12 = 'Points-Table'!$A$9), 'Points-Table'!$C$9, (S12 = 'Points-Table'!$A$10), 'Points-Table'!$C$10, (S12 = 'Points-Table'!$A$11), 'Points-Table'!$C$11, (S12 = 'Points-Table'!$A$12), 'Points-Table'!$C$12, (S12 = 'Points-Table'!$A$13), 'Points-Table'!$C$13, true, 0 ) | U12: 0 | V12: =Ifs( (U12 = 'Points-Table'!$A$4), 'Points-Table'!$C$4, (U12 = 'Points-Table'!$A$5), 'Points-Table'!$C$5, (U12 = 'Points-Table'!$A$6), 'Points-Table'!$C$6, (U12 = 'Points-Table'!$A$7), 'Points-Table'!$C$7, (U12 = 'Points-Table'!$A$8), 'Points-Table'!$C$8, (U12 = 'Points-Table'!$A$9), 'Points-Table'!$C$9, (U12 = 'Points-Table'!$A$10), 'Points-Table'!$C$10, (U12 = 'Points-Table'!$A$11), 'Points-Table'!$C$11, (U12 = 'Points-Table'!$A$12), 'Points-Table'!$C$12, (U12 = 'Points-Table'!$A$13), 'Points-Table'!$C$13, true, 0 ) | W12: 0 | X12: =Ifs( (W12 = 'Points-Table'!$A$4), 'Points-Table'!$C$4, (W12 = 'Points-Table'!$A$5), 'Points-Table'!$C$5, (W12 = 'Points-Table'!$A$6), 'Points-Table'!$C$6, (W12 = 'Points-Table'!$A$7), 'Points-Table'!$C$7, (W12 = 'Points-Table'!$A$8), 'Points-Table'!$C$8, (W12 = 'Points-Table'!$A$9), 'Points-Table'!$C$9, (W12 = 'Points-Table'!$A$10), 'Points-Table'!$C$10, (W12 = 'Points-Table'!$A$11), 'Points-Table'!$C$11, (W12 = 'Points-Table'!$A$12), 'Points-Table'!$C$12, (W12 = 'Points-Table'!$A$13), 'Points-Table'!$C$13, true, 0 ) | Y12: 0 | Z12: =Ifs( (Y12 = 'Points-Table'!$A$4), 'Points-Table'!$C$4, (Y12 = 'Points-Table'!$A$5), 'Points-Table'!$C$5, (Y12 = 'Points-Table'!$A$6), 'Points-Table'!$C$6, (Y12 = 'Points-Table'!$A$7), 'Points-Table'!$C$7, (Y12 = 'Points-Table'!$A$8), 'Points-Table'!$C$8, (Y12 = 'Points-Table'!$A$9), 'Points-Table'!$C$9, (Y12 = 'Points-Table'!$A$10), 'Points-Table'!$C$10, (Y12 = 'Points-Table'!$A$11), 'Points-Table'!$C$11, (Y12 = 'Points-Table'!$A$12), 'Points-Table'!$C$12, (Y12 = 'Points-Table'!$A$13), 'Points-Table'!$C$13, true, 0 ) | AA12: =SUM(V12,X12,Z12) | AB12: =Ifs( ISBETWEEN(AA12, 0, 'Points-Table'!C$20, TRUE, False), 'Points-Table'!A$20, ISBETWEEN(AA12, 'Points-Table'!C$20, 'Points-Table'!C$21, TRUE, False), 'Points-Table'!A$21, ISBETWEEN(AA12, 'Points-Table'!C$22, 10000, TRUE, TRUE), 'Points-Table'!A$22, true, 0)
A13: Home | B13: Hero section | D13: 4-5 auto scrollable banner images | K13: Simple | L13: Must Have | Q13: 0 | R13: =Ifs( (Q13 = 'Points-Table'!$A$4), 'Points-Table'!$C$4, (Q13 = 'Points-Table'!$A$5), 'Points-Table'!$C$5, (Q13 = 'Points-Table'!$A$6), 'Points-Table'!$C$6, (Q13 = 'Points-Table'!$A$7), 'Points-Table'!$C$7, (Q13 = 'Points-Table'!$A$8), 'Points-Table'!$C$8, (Q13 = 'Points-Table'!$A$9), 'Points-Table'!$C$9, (Q13 = 'Points-Table'!$A$10), 'Points-Table'!$C$10, (Q13 = 'Points-Table'!$A$11), 'Points-Table'!$C$11, (Q13 = 'Points-Table'!$A$12), 'Points-Table'!$C$12, (Q13 = 'Points-Table'!$A$13), 'Points-Table'!$C$13, true, 0 ) | S13: 0 | T13: =Ifs( (S13 = 'Points-Table'!$A$4), 'Points-Table'!$C$4, (S13 = 'Points-Table'!$A$5), 'Points-Table'!$C$5, (S13 = 'Points-Table'!$A$6), 'Points-Table'!$C$6, (S13 = 'Points-Table'!$A$7), 'Points-Table'!$C$7, (S13 = 'Points-Table'!$A$8), 'Points-Table'!$C$8, (S13 = 'Points-Table'!$A$9), 'Points-Table'!$C$9, (S13 = 'Points-Table'!$A$10), 'Points-Table'!$C$10, (S13 = 'Points-Table'!$A$11), 'Points-Table'!$C$11, (S13 = 'Points-Table'!$A$12), 'Points-Table'!$C$12, (S13 = 'Points-Table'!$A$13), 'Points-Table'!$C$13, true, 0 ) | U13: 5 | V13: =Ifs( (U13 = 'Points-Table'!$A$4), 'Points-Table'!$C$4, (U13 = 'Points-Table'!$A$5), 'Points-Table'!$C$5, (U13 = 'Points-Table'!$A$6), 'Points-Table'!$C$6, (U13 = 'Points-Table'!$A$7), 'Points-Table'!$C$7, (U13 = 'Points-Table'!$A$8), 'Points-Table'!$C$8, (U13 = 'Points-Table'!$A$9), 'Points-Table'!$C$9, (U13 = 'Points-Table'!$A$10), 'Points-Table'!$C$10, (U13 = 'Points-Table'!$A$11), 'Points-Table'!$C$11, (U13 = 'Points-Table'!$A$12), 'Points-Table'!$C$12, (U13 = 'Points-Table'!$A$13), 'Points-Table'!$C$13, true, 0 ) | W13: 2 | X13: =Ifs( (W13 = 'Points-Table'!$A$4), 'Points-Table'!$C$4, (W13 = 'Points-Table'!$A$5), 'Points-Table'!$C$5, (W13 = 'Points-Table'!$A$6), 'Points-Table'!$C$6, (W13 = 'Points-Table'!$A$7), 'Points-Table'!$C$7, (W13 = 'Points-Table'!$A$8), 'Points-Table'!$C$8, (W13 = 'Points-Table'!$A$9), 'Points-Table'!$C$9, (W13 = 'Points-Table'!$A$10), 'Points-Table'!$C$10, (W13 = 'Points-Table'!$A$11), 'Points-Table'!$C$11, (W13 = 'Points-Table'!$A$12), 'Points-Table'!$C$12, (W13 = 'Points-Table'!$A$13), 'Points-Table'!$C$13, true, 0 ) | Y13: 0 | Z13: =Ifs( (Y13 = 'Points-Table'!$A$4), 'Points-Table'!$C$4, (Y13 = 'Points-Table'!$A$5), 'Points-Table'!$C$5, (Y13 = 'Points-Table'!$A$6), 'Points-Table'!$C$6, (Y13 = 'Points-Table'!$A$7), 'Points-Table'!$C$7, (Y13 = 'Points-Table'!$A$8), 'Points-Table'!$C$8, (Y13 = 'Points-Table'!$A$9), 'Points-Table'!$C$9, (Y13 = 'Points-Table'!$A$10), 'Points-Table'!$C$10, (Y13 = 'Points-Table'!$A$11), 'Points-Table'!$C$11, (Y13 = 'Points-Table'!$A$12), 'Points-Table'!$C$12, (Y13 = 'Points-Table'!$A$13), 'Points-Table'!$C$13, true, 0 ) | AA13: =SUM(V13,X13,Z13) | AB13: =Ifs( ISBETWEEN(AA13, 0, 'Points-Table'!C$20, TRUE, False), 'Points-Table'!A$20, ISBETWEEN(AA13, 'Points-Table'!C$20, 'Points-Table'!C$21, TRUE, False), 'Points-Table'!A$21, ISBETWEEN(AA13, 'Points-Table'!C$22, 10000, TRUE, TRUE), 'Points-Table'!A$22, true, 0)
A14: Home | B14: Upcoming attraction & Monthly lotteries | K14: Simple | L14: Must Have | Q14: 0 | R14: =Ifs( (Q14 = 'Points-Table'!$A$4), 'Points-Table'!$C$4, (Q14 = 'Points-Table'!$A$5), 'Points-Table'!$C$5, (Q14 = 'Points-Table'!$A$6), 'Points-Table'!$C$6, (Q14 = 'Points-Table'!$A$7), 'Points-Table'!$C$7, (Q14 = 'Points-Table'!$A$8), 'Points-Table'!$C$8, (Q14 = 'Points-Table'!$A$9), 'Points-Table'!$C$9, (Q14 = 'Points-Table'!$A$10), 'Points-Table'!$C$10, (Q14 = 'Points-Table'!$A$11), 'Points-Table'!$C$11, (Q14 = 'Points-Table'!$A$12), 'Points-Table'!$C$12, (Q14 = 'Points-Table'!$A$13), 'Points-Table'!$C$13, true, 0 ) | S14: 0 | T14: =Ifs( (S14 = 'Points-Table'!$A$4), 'Points-Table'!$C$4, (S14 = 'Points-Table'!$A$5), 'Points-Table'!$C$5, (S14 = 'Points-Table'!$A$6), 'Points-Table'!$C$6, (S14 = 'Points-Table'!$A$7), 'Points-Table'!$C$7, (S14 = 'Points-Table'!$A$8), 'Points-Table'!$C$8, (S14 = 'Points-Table'!$A$9), 'Points-Table'!$C$9, (S14 = 'Points-Table'!$A$10), 'Points-Table'!$C$10, (S14 = 'Points-Table'!$A$11), 'Points-Table'!$C$11, (S14 = 'Points-Table'!$A$12), 'Points-Table'!$C$12, (S14 = 'Points-Table'!$A$13), 'Points-Table'!$C$13, true, 0 ) | U14: 21 | V14: =Ifs( (U14 = 'Points-Table'!$A$4), 'Points-Table'!$C$4, (U14 = 'Points-Table'!$A$5), 'Points-Table'!$C$5, (U14 = 'Points-Table'!$A$6), 'Points-Table'!$C$6, (U14 = 'Points-Table'!$A$7), 'Points-Table'!$C$7, (U14 = 'Points-Table'!$A$8), 'Points-Table'!$C$8, (U14 = 'Points-Table'!$A$9), 'Points-Table'!$C$9, (U14 = 'Points-Table'!$A$10), 'Points-Table'!$C$10, (U14 = 'Points-Table'!$A$11), 'Points-Table'!$C$11, (U14 = 'Points-Table'!$A$12), 'Points-Table'!$C$12, (U14 = 'Points-Table'!$A$13), 'Points-Table'!$C$13, true, 0 ) | W14: 2 | X14: =Ifs( (W14 = 'Points-Table'!$A$4), 'Points-Table'!$C$4, (W14 = 'Points-Table'!$A$5), 'Points-Table'!$C$5, (W14 = 'Points-Table'!$A$6), 'Points-Table'!$C$6, (W14 = 'Points-Table'!$A$7), 'Points-Table'!$C$7, (W14 = 'Points-Table'!$A$8), 'Points-Table'!$C$8, (W14 = 'Points-Table'!$A$9), 'Points-Table'!$C$9, (W14 = 'Points-Table'!$A$10), 'Points-Table'!$C$10, (W14 = 'Points-Table'!$A$11), 'Points-Table'!$C$11, (W14 = 'Points-Table'!$A$12), 'Points-Table'!$C$12, (W14 = 'Points-Table'!$A$13), 'Points-Table'!$C$13, true, 0 ) | Y14: 0 | Z14: =Ifs( (Y14 = 'Points-Table'!$A$4), 'Points-Table'!$C$4, (Y14 = 'Points-Table'!$A$5), 'Points-Table'!$C$5, (Y14 = 'Points-Table'!$A$6), 'Points-Table'!$C$6, (Y14 = 'Points-Table'!$A$7), 'Points-Table'!$C$7, (Y14 = 'Points-Table'!$A$8), 'Points-Table'!$C$8, (Y14 = 'Points-Table'!$A$9), 'Points-Table'!$C$9, (Y14 = 'Points-Table'!$A$10), 'Points-Table'!$C$10, (Y14 = 'Points-Table'!$A$11), 'Points-Table'!$C$11, (Y14 = 'Points-Table'!$A$12), 'Points-Table'!$C$12, (Y14 = 'Points-Table'!$A$13), 'Points-Table'!$C$13, true, 0 ) | AA14: =SUM(V14,X14,Z14) | AB14: =Ifs( ISBETWEEN(AA14, 0, 'Points-Table'!C$20, TRUE, False), 'Points-Table'!A$20, ISBETWEEN(AA14, 'Points-Table'!C$20, 'Points-Table'!C$21, TRUE, False), 'Points-Table'!A$21, ISBETWEEN(AA14, 'Points-Table'!C$22, 10000, TRUE, TRUE), 'Points-Table'!A$22, true, 0)
A15: Home | B15: Recent Winners | K15: Simple | L15: Must Have | Q15: 0 | R15: =Ifs( (Q15 = 'Points-Table'!$A$4), 'Points-Table'!$C$4, (Q15 = 'Points-Table'!$A$5), 'Points-Table'!$C$5, (Q15 = 'Points-Table'!$A$6), 'Points-Table'!$C$6, (Q15 = 'Points-Table'!$A$7), 'Points-Table'!$C$7, (Q15 = 'Points-Table'!$A$8), 'Points-Table'!$C$8, (Q15 = 'Points-Table'!$A$9), 'Points-Table'!$C$9, (Q15 = 'Points-Table'!$A$10), 'Points-Table'!$C$10, (Q15 = 'Points-Table'!$A$11), 'Points-Table'!$C$11, (Q15 = 'Points-Table'!$A$12), 'Points-Table'!$C$12, (Q15 = 'Points-Table'!$A$13), 'Points-Table'!$C$13, true, 0 ) | S15: 0 | T15: =Ifs( (S15 = 'Points-Table'!$A$4), 'Points-Table'!$C$4, (S15 = 'Points-Table'!$A$5), 'Points-Table'!$C$5, (S15 = 'Points-Table'!$A$6), 'Points-Table'!$C$6, (S15 = 'Points-Table'!$A$7), 'Points-Table'!$C$7, (S15 = 'Points-Table'!$A$8), 'Points-Table'!$C$8, (S15 = 'Points-Table'!$A$9), 'Points-Table'!$C$9, (S15 = 'Points-Table'!$A$10), 'Points-Table'!$C$10, (S15 = 'Points-Table'!$A$11), 'Points-Table'!$C$11, (S15 = 'Points-Table'!$A$12), 'Points-Table'!$C$12, (S15 = 'Points-Table'!$A$13), 'Points-Table'!$C$13, true, 0 ) | U15: 5 | V15: =Ifs( (U15 = 'Points-Table'!$A$4), 'Points-Table'!$C$4, (U15 = 'Points-Table'!$A$5), 'Points-Table'!$C$5, (U15 = 'Points-Table'!$A$6), 'Points-Table'!$C$6, (U15 = 'Points-Table'!$A$7), 'Points-Table'!$C$7, (U15 = 'Points-Table'!$A$8), 'Points-Table'!$C$8, (U15 = 'Points-Table'!$A$9), 'Points-Table'!$C$9, (U15 = 'Points-Table'!$A$10), 'Points-Table'!$C$10, (U15 = 'Points-Table'!$A$11), 'Points-Table'!$C$11, (U15 = 'Points-Table'!$A$12), 'Points-Table'!$C$12, (U15 = 'Points-Table'!$A$13), 'Points-Table'!$C$13, true, 0 ) | W15: 2 | X15: =Ifs( (W15 = 'Points-Table'!$A$4), 'Points-Table'!$C$4, (W15 = 'Points-Table'!$A$5), 'Points-Table'!$C$5, (W15 = 'Points-Table'!$A$6), 'Points-Table'!$C$6, (W15 = 'Points-Table'!$A$7), 'Points-Table'!$C$7, (W15 = 'Points-Table'!$A$8), 'Points-Table'!$C$8, (W15 = 'Points-Table'!$A$9), 'Points-Table'!$C$9, (W15 = 'Points-Table'!$A$10), 'Points-Table'!$C$10, (W15 = 'Points-Table'!$A$11), 'Points-Table'!$C$11, (W15 = 'Points-Table'!$A$12), 'Points-Table'!$C$12, (W15 = 'Points-Table'!$A$13), 'Points-Table'!$C$13, true, 0 ) | Y15: 0 | Z15: =Ifs( (Y15 = 'Points-Table'!$A$4), 'Points-Table'!$C$4, (Y15 = 'Points-Table'!$A$5), 'Points-Table'!$C$5, (Y15 = 'Points-Table'!$A$6), 'Points-Table'!$C$6, (Y15 = 'Points-Table'!$A$7), 'Points-Table'!$C$7, (Y15 = 'Points-Table'!$A$8), 'Points-Table'!$C$8, (Y15 = 'Points-Table'!$A$9), 'Points-Table'!$C$9, (Y15 = 'Points-Table'!$A$10), 'Points-Table'!$C$10, (Y15 = 'Points-Table'!$A$11), 'Points-Table'!$C$11, (Y15 = 'Points-Table'!$A$12), 'Points-Table'!$C$12, (Y15 = 'Points-Table'!$A$13), 'Points-Table'!$C$13, true, 0 ) | AA15: =SUM(V15,X15,Z15) | AB15: =Ifs( ISBETWEEN(AA15, 0, 'Points-Table'!C$20, TRUE, False), 'Points-Table'!A$20, ISBETWEEN(AA15, 'Points-Table'!C$20, 'Points-Table'!C$21, TRUE, False), 'Points-Table'!A$21, ISBETWEEN(AA15, 'Points-Table'!C$22, 10000, TRUE, TRUE), 'Points-Table'!A$22, true, 0)
A16: Home | B16: How to play out lotteries? | F16: Youtube video URL will be shared | K16: Simple | L16: Must Have | Q16: 0 | R16: =Ifs( (Q16 = 'Points-Table'!$A$4), 'Points-Table'!$C$4, (Q16 = 'Points-Table'!$A$5), 'Points-Table'!$C$5, (Q16 = 'Points-Table'!$A$6), 'Points-Table'!$C$6, (Q16 = 'Points-Table'!$A$7), 'Points-Table'!$C$7, (Q16 = 'Points-Table'!$A$8), 'Points-Table'!$C$8, (Q16 = 'Points-Table'!$A$9), 'Points-Table'!$C$9, (Q16 = 'Points-Table'!$A$10), 'Points-Table'!$C$10, (Q16 = 'Points-Table'!$A$11), 'Points-Table'!$C$11, (Q16 = 'Points-Table'!$A$12), 'Points-Table'!$C$12, (Q16 = 'Points-Table'!$A$13), 'Points-Table'!$C$13, true, 0 ) | S16: 0 | T16: =Ifs( (S16 = 'Points-Table'!$A$4), 'Points-Table'!$C$4, (S16 = 'Points-Table'!$A$5), 'Points-Table'!$C$5, (S16 = 'Points-Table'!$A$6), 'Points-Table'!$C$6, (S16 = 'Points-Table'!$A$7), 'Points-Table'!$C$7, (S16 = 'Points-Table'!$A$8), 'Points-Table'!$C$8, (S16 = 'Points-Table'!$A$9), 'Points-Table'!$C$9, (S16 = 'Points-Table'!$A$10), 'Points-Table'!$C$10, (S16 = 'Points-Table'!$A$11), 'Points-Table'!$C$11, (S16 = 'Points-Table'!$A$12), 'Points-Table'!$C$12, (S16 = 'Points-Table'!$A$13), 'Points-Table'!$C$13, true, 0 ) | U16: 3 | V16: =Ifs( (U16 = 'Points-Table'!$A$4), 'Points-Table'!$C$4, (U16 = 'Points-Table'!$A$5), 'Points-Table'!$C$5, (U16 = 'Points-Table'!$A$6), 'Points-Table'!$C$6, (U16 = 'Points-Table'!$A$7), 'Points-Table'!$C$7, (U16 = 'Points-Table'!$A$8), 'Points-Table'!$C$8, (U16 = 'Points-Table'!$A$9), 'Points-Table'!$C$9, (U16 = 'Points-Table'!$A$10), 'Points-Table'!$C$10, (U16 = 'Points-Table'!$A$11), 'Points-Table'!$C$11, (U16 = 'Points-Table'!$A$12), 'Points-Table'!$C$12, (U16 = 'Points-Table'!$A$13), 'Points-Table'!$C$13, true, 0 ) | W16: 0 | X16: =Ifs( (W16 = 'Points-Table'!$A$4), 'Points-Table'!$C$4, (W16 = 'Points-Table'!$A$5), 'Points-Table'!$C$5, (W16 = 'Points-Table'!$A$6), 'Points-Table'!$C$6, (W16 = 'Points-Table'!$A$7), 'Points-Table'!$C$7, (W16 = 'Points-Table'!$A$8), 'Points-Table'!$C$8, (W16 = 'Points-Table'!$A$9), 'Points-Table'!$C$9, (W16 = 'Points-Table'!$A$10), 'Points-Table'!$C$10, (W16 = 'Points-Table'!$A$11), 'Points-Table'!$C$11, (W16 = 'Points-Table'!$A$12), 'Points-Table'!$C$12, (W16 = 'Points-Table'!$A$13), 'Points-Table'!$C$13, true, 0 ) | Y16: 0 | Z16: =Ifs( (Y16 = 'Points-Table'!$A$4), 'Points-Table'!$C$4, (Y16 = 'Points-Table'!$A$5), 'Points-Table'!$C$5, (Y16 = 'Points-Table'!$A$6), 'Points-Table'!$C$6, (Y16 = 'Points-Table'!$A$7), 'Points-Table'!$C$7, (Y16 = 'Points-Table'!$A$8), 'Points-Table'!$C$8, (Y16 = 'Points-Table'!$A$9), 'Points-Table'!$C$9, (Y16 = 'Points-Table'!$A$10), 'Points-Table'!$C$10, (Y16 = 'Points-Table'!$A$11), 'Points-Table'!$C$11, (Y16 = 'Points-Table'!$A$12), 'Points-Table'!$C$12, (Y16 = 'Points-Table'!$A$13), 'Points-Table'!$C$13, true, 0 ) | AA16: =SUM(V16,X16,Z16) | AB16: =Ifs( ISBETWEEN(AA16, 0, 'Points-Table'!C$20, TRUE, False), 'Points-Table'!A$20, ISBETWEEN(AA16, 'Points-Table'!C$20, 'Points-Table'!C$21, TRUE, False), 'Points-Table'!A$21, ISBETWEEN(AA16, 'Points-Table'!C$22, 10000, TRUE, TRUE), 'Points-Table'!A$22, true, 0)
A17: Home | B17: Header | K17: Simple | L17: Must Have | Q17: 0 | R17: =Ifs( (Q17 = 'Points-Table'!$A$4), 'Points-Table'!$C$4, (Q17 = 'Points-Table'!$A$5), 'Points-Table'!$C$5, (Q17 = 'Points-Table'!$A$6), 'Points-Table'!$C$6, (Q17 = 'Points-Table'!$A$7), 'Points-Table'!$C$7, (Q17 = 'Points-Table'!$A$8), 'Points-Table'!$C$8, (Q17 = 'Points-Table'!$A$9), 'Points-Table'!$C$9, (Q17 = 'Points-Table'!$A$10), 'Points-Table'!$C$10, (Q17 = 'Points-Table'!$A$11), 'Points-Table'!$C$11, (Q17 = 'Points-Table'!$A$12), 'Points-Table'!$C$12, (Q17 = 'Points-Table'!$A$13), 'Points-Table'!$C$13, true, 0 ) | S17: 0 | T17: =Ifs( (S17 = 'Points-Table'!$A$4), 'Points-Table'!$C$4, (S17 = 'Points-Table'!$A$5), 'Points-Table'!$C$5, (S17 = 'Points-Table'!$A$6), 'Points-Table'!$C$6, (S17 = 'Points-Table'!$A$7), 'Points-Table'!$C$7, (S17 = 'Points-Table'!$A$8), 'Points-Table'!$C$8, (S17 = 'Points-Table'!$A$9), 'Points-Table'!$C$9, (S17 = 'Points-Table'!$A$10), 'Points-Table'!$C$10, (S17 = 'Points-Table'!$A$11), 'Points-Table'!$C$11, (S17 = 'Points-Table'!$A$12), 'Points-Table'!$C$12, (S17 = 'Points-Table'!$A$13), 'Points-Table'!$C$13, true, 0 ) | U17: 3 | V17: =Ifs( (U17 = 'Points-Table'!$A$4), 'Points-Table'!$C$4, (U17 = 'Points-Table'!$A$5), 'Points-Table'!$C$5, (U17 = 'Points-Table'!$A$6), 'Points-Table'!$C$6, (U17 = 'Points-Table'!$A$7), 'Points-Table'!$C$7, (U17 = 'Points-Table'!$A$8), 'Points-Table'!$C$8, (U17 = 'Points-Table'!$A$9), 'Points-Table'!$C$9, (U17 = 'Points-Table'!$A$10), 'Points-Table'!$C$10, (U17 = 'Points-Table'!$A$11), 'Points-Table'!$C$11, (U17 = 'Points-Table'!$A$12), 'Points-Table'!$C$12, (U17 = 'Points-Table'!$A$13), 'Points-Table'!$C$13, true, 0 ) | W17: 0 | X17: =Ifs( (W17 = 'Points-Table'!$A$4), 'Points-Table'!$C$4, (W17 = 'Points-Table'!$A$5), 'Points-Table'!$C$5, (W17 = 'Points-Table'!$A$6), 'Points-Table'!$C$6, (W17 = 'Points-Table'!$A$7), 'Points-Table'!$C$7, (W17 = 'Points-Table'!$A$8), 'Points-Table'!$C$8, (W17 = 'Points-Table'!$A$9), 'Points-Table'!$C$9, (W17 = 'Points-Table'!$A$10), 'Points-Table'!$C$10, (W17 = 'Points-Table'!$A$11), 'Points-Table'!$C$11, (W17 = 'Points-Table'!$A$12), 'Points-Table'!$C$12, (W17 = 'Points-Table'!$A$13), 'Points-Table'!$C$13, true, 0 ) | Y17: 0 | Z17: =Ifs( (Y17 = 'Points-Table'!$A$4), 'Points-Table'!$C$4, (Y17 = 'Points-Table'!$A$5), 'Points-Table'!$C$5, (Y17 = 'Points-Table'!$A$6), 'Points-Table'!$C$6, (Y17 = 'Points-Table'!$A$7), 'Points-Table'!$C$7, (Y17 = 'Points-Table'!$A$8), 'Points-Table'!$C$8, (Y17 = 'Points-Table'!$A$9), 'Points-Table'!$C$9, (Y17 = 'Points-Table'!$A$10), 'Points-Table'!$C$10, (Y17 = 'Points-Table'!$A$11), 'Points-Table'!$C$11, (Y17 = 'Points-Table'!$A$12), 'Points-Table'!$C$12, (Y17 = 'Points-Table'!$A$13), 'Points-Table'!$C$13, true, 0 ) | AA17: =SUM(V17,X17,Z17) | AB17: =Ifs( ISBETWEEN(AA17, 0, 'Points-Table'!C$20, TRUE, False), 'Points-Table'!A$20, ISBETWEEN(AA17, 'Points-Table'!C$20, 'Points-Table'!C$21, TRUE, False), 'Points-Table'!A$21, ISBETWEEN(AA17, 'Points-Table'!C$22, 10000, TRUE, TRUE), 'Points-Table'!A$22, true, 0)
