Workbook

Sheet User Application - Dev
A1: Module Name | B1: Feature | C1: Sub-Feature | D1: Description | E1: Reference Link | F1: Assumption | G1: Queries | H1: Prototype Link | I1: What to do? | J1: How to do? | K1: Complexity | L1: Priority | M1: Frequency | N1: Design Available | O1: Required Development | P1: NPM Packages | Q1: Wireframes Story Points | R1: =SUM(R2:R1006) -> 85 | S1: Visual Design Story Points | T1: =SUM(T2:T1006) -> 66 | U1: Frontend Story Points | V1: =SUM(V2:V1006) -> 275 | W1: Integration Story Points | X1: =SUM(X2:X1006) -> 337 | Y1: Backend Story Points | Z1: =SUM(Z2:Z1006) -> 178 | AA1: =SUM(AA2:AA1006) -> 790 | AB1: T-Shirt Size | AC1: Tags | AD1: Screen Patterns | AE1: Feature Categories
A2: Landing Page | K2: Simple | L2: Must Have | Q2: 21 | R2: =Ifs( (Q2 = 'Points-Table'!$A$4), 'Points-Table'!$C$4, (Q2 = 'Points-Table'!$A$5), 'Points-Table'!$C$5, (Q2 = 'Points-Table'!$A$6), 'Points-Table'!$C$6, (Q2 = 'Points-Table'!$A$7), 'Points-Table'!$C$7, (Q2 = 'Points-Table'!$A$8), 'Points-Table'!$C$8, (Q2 = 'Points-Table'!$A$9), 'Points-Table'!$C$9, (Q2 = 'Points-Table'!$A$10), 'Points-Table'!$C$10, (Q2 = 'Points-Table'!$A$11), 'Points-Table'!$C$11, (Q2 = 'Points-Table'!$A$12), 'Points-Table'!$C$12, (Q2 = 'Points-Table'!$A$13), 'Points-Table'!$C$13, true, 0 ) -> 16 | S2: 21 | T2: =Ifs( (S2 = 'Points-Table'!$A$4), 'Points-Table'!$C$4, (S2 = 'Points-Table'!$A$5), 'Points-Table'!$C$5, (S2 = 'Points-Table'!$A$6), 'Points-Table'!$C$6, (S2 = 'Points-Table'!$A$7), 'Points-Table'!$C$7, (S2 = 'Points-Table'!$A$8), 'Points-Table'!$C$8, (S2 = 'Points-Table'!$A$9), 'Points-Table'!$C$9, (S2 = 'Points-Table'!$A$10), 'Points-Table'!$C$10, (S2 = 'Points-Table'!$A$11), 'Points-Table'!$C$11, (S2 = 'Points-Table'!$A$12), 'Points-Table'!$C$12, (S2 = 'Points-Table'!$A$13), 'Points-Table'!$C$13, true, 0 ) -> 16 | U2: 3 | V2: =Ifs( (U2 = 'Points-Table'!$A$4), 'Points-Table'!$C$4, (U2 = 'Points-Table'!$A$5), 'Points-Table'!$C$5, (U2 = 'Points-Table'!$A$6), 'Points-Table'!$C$6, (U2 = 'Points-Table'!$A$7), 'Points-Table'!$C$7, (U2 = 'Points-Table'!$A$8), 'Points-Table'!$C$8, (U2 = 'Points-Table'!$A$9), 'Points-Table'!$C$9, (U2 = 'Points-Table'!$A$10), 'Points-Table'!$C$10, (U2 = 'Points-Table'!$A$11), 'Points-Table'!$C$11, (U2 = 'Points-Table'!$A$12), 'Points-Table'!$C$12, (U2 = 'Points-Table'!$A$13), 'Points-Table'!$C$13, true, 0 ) -> 2 | X2: =Ifs( (W2 = 'Points-Table'!$A$4), 'Points-Table'!$C$4, (W2 = 'Points-Table'!$A$5), 'Points-Table'!$C$5, (W2 = 'Points-Table'!$A$6), 'Points-Table'!$C$6, (W2 = 'Points-Table'!$A$7), 'Points-Table'!$C$7, (W2 = 'Points-Table'!$A$8), 'Points-Table'!$C$8, (W2 = 'Points-Table'!$A$9), 'Points-Table'!$C$9, (W2 = 'Points-Table'!$A$10), 'Points-Table'!$C$10, (W2 = 'Points-Table'!$A$11), 'Points-Table'!$C$11, (W2 = 'Points-Table'!$A$12), 'Points-Table'!$C$12, (W2 = 'Points-Table'!$A$13), 'Points-Table'!$C$13, true, 0 ) -> 0 | Z2: =Ifs( (Y2 = 'Points-Table'!$A$4), 'Points-Table'!$C$4, (Y2 = 'Points-Table'!$A$5), 'Points-Table'!$C$5, (Y2 = 'Points-Table'!$A$6), 'Points-Table'!$C$6, (Y2 = 'Points-Table'!$A$7), 'Points-Table'!$C$7, (Y2 = 'Points-Table'!$A$8), 'Points-Table'!$C$8, (Y2 = 'Points-Table'!$A$9), 'Points-Table'!$C$9, (Y2 = 'Points-Table'!$A$10), 'Points-Table'!$C$10, (Y2 = 'Points-Table'!$A$11), 'Points-Table'!$C$11, (Y2 = 'Points-Table'!$A$12), 'Points-Table'!$C$12, (Y2 = 'Points-Table'!$A$13), 'Points-Table'!$C$13, true, 0 ) -> 0 | AA2: =SUM(V2,X2,Z2) -> 2 | AB2: =IFERROR(__xludf.DUMMYFUNCTION(" Ifs( ISBETWEEN(AA2, 0, 'Points-Table'!C$20, TRUE, False), 'Points-Table'!A$20, ISBETWEEN(AA2, 'Points-Table'!C$20, 'Points-Table'!C$21, TRUE, False), 'Points-Table'!A$21, ISBETWEEN(AA2, 'Points-Table'!C$22, 10000, TRUE, TRU"&"E), 'Points-Table'!A$22, true, 0) "),"S") -> S
A3: Registration | B3: Basic Details | Email Id | Username | K3: Simple | L3: Must Have | Q3: 2 | R3: =Ifs( (Q3 = 'Points-Table'!$A$4), 'Points-Table'!$C$4, (Q3 = 'Points-Table'!$A$5), 'Points-Table'!$C$5, (Q3 = 'Points-Table'!$A$6), 'Points-Table'!$C$6, (Q3 = 'Points-Table'!$A$7), 'Points-Table'!$C$7, (Q3 = 'Points-Table'!$A$8), 'Points-Table'!$C$8, (Q3 = 'Points-Table'!$A$9), 'Points-Table'!$C$9, (Q3 = 'Points-Table'!$A$10), 'Points-Table'!$C$10, (Q3 = 'Points-Table'!$A$11), 'Points-Table'!$C$11, (Q3 = 'Points-Table'!$A$12), 'Points-Table'!$C$12, (Q3 = 'Points-Table'!$A$13), 'Points-Table'!$C$13, true, 0 ) -> 1 | S3: 2 | T3: =Ifs( (S3 = 'Points-Table'!$A$4), 'Points-Table'!$C$4, (S3 = 'Points-Table'!$A$5), 'Points-Table'!$C$5, (S3 = 'Points-Table'!$A$6), 'Points-Table'!$C$6, (S3 = 'Points-Table'!$A$7), 'Points-Table'!$C$7, (S3 = 'Points-Table'!$A$8), 'Points-Table'!$C$8, (S3 = 'Points-Table'!$A$9), 'Points-Table'!$C$9, (S3 = 'Points-Table'!$A$10), 'Points-Table'!$C$10, (S3 = 'Points-Table'!$A$11), 'Points-Table'!$C$11, (S3 = 'Points-Table'!$A$12), 'Points-Table'!$C$12, (S3 = 'Points-Table'!$A$13), 'Points-Table'!$C$13, true, 0 ) -> 1 | U3: 5 | V3: =Ifs( (U3 = 'Points-Table'!$A$4), 'Points-Table'!$C$4, (U3 = 'Points-Table'!$A$5), 'Points-Table'!$C$5, (U3 = 'Points-Table'!$A$6), 'Points-Table'!$C$6, (U3 = 'Points-Table'!$A$7), 'Points-Table'!$C$7, (U3 = 'Points-Table'!$A$8), 'Points-Table'!$C$8, (U3 = 'Points-Table'!$A$9), 'Points-Table'!$C$9, (U3 = 'Points-Table'!$A$10), 'Points-Table'!$C$10, (U3 = 'Points-Table'!$A$11), 'Points-Table'!$C$11, (U3 = 'Points-Table'!$A$12), 'Points-Table'!$C$12, (U3 = 'Points-Table'!$A$13), 'Points-Table'!$C$13, true, 0 ) -> 4 | W3: 5 | X3: =Ifs( (W3 = 'Points-Table'!$A$4), 'Points-Table'!$C$4, (W3 = 'Points-Table'!$A$5), 'Points-Table'!$C$5, (W3 = 'Points-Table'!$A$6), 'Points-Table'!$C$6, (W3 = 'Points-Table'!$A$7), 'Points-Table'!$C$7, (W3 = 'Points-Table'!$A$8), 'Points-Table'!$C$8, (W3 = 'Points-Table'!$A$9), 'Points-Table'!$C$9, (W3 = 'Points-Table'!$A$10), 'Points-Table'!$C$10, (W3 = 'Points-Table'!$A$11), 'Points-Table'!$C$11, (W3 = 'Points-Table'!$A$12), 'Points-Table'!$C$12, (W3 = 'Points-Table'!$A$13), 'Points-Table'!$C$13, true, 0 ) -> 4 | Z3: =Ifs( (Y3 = 'Points-Table'!$A$4), 'Points-Table'!$C$4, (Y3 = 'Points-Table'!$A$5), 'Points-Table'!$C$5, (Y3 = 'Points-Table'!$A$6), 'Points-Table'!$C$6, (Y3 = 'Points-Table'!$A$7), 'Points-Table'!$C$7, (Y3 = 'Points-Table'!$A$8), 'Points-Table'!$C$8, (Y3 = 'Points-Table'!$A$9), 'Points-Table'!$C$9, (Y3 = 'Points-Table'!$A$10), 'Points-Table'!$C$10, (Y3 = 'Points-Table'!$A$11), 'Points-Table'!$C$11, (Y3 = 'Points-Table'!$A$12), 'Points-Table'!$C$12, (Y3 = 'Points-Table'!$A$13), 'Points-Table'!$C$13, true, 0 ) -> 0 | AA3: =SUM(V3,X3,Z3) -> 8 | AB3: =IFERROR(__xludf.DUMMYFUNCTION(" Ifs( ISBETWEEN(AA3, 0, 'Points-Table'!C$20, TRUE, False), 'Points-Table'!A$20, ISBETWEEN(AA3, 'Points-Table'!C$20, 'Points-Table'!C$21, TRUE, False), 'Points-Table'!A$21, ISBETWEEN(AA3, 'Points-Table'!C$22, 10000, TRUE, TRU"&"E), 'Points-Table'!A$22, true, 0) "),"S") -> S
A4: Registration | B4: OTP Verification (O-auth) | K4: Simple | L4: Must Have | R4: =Ifs( (Q4 = 'Points-Table'!$A$4), 'Points-Table'!$C$4, (Q4 = 'Points-Table'!$A$5), 'Points-Table'!$C$5, (Q4 = 'Points-Table'!$A$6), 'Points-Table'!$C$6, (Q4 = 'Points-Table'!$A$7), 'Points-Table'!$C$7, (Q4 = 'Points-Table'!$A$8), 'Points-Table'!$C$8, (Q4 = 'Points-Table'!$A$9), 'Points-Table'!$C$9, (Q4 = 'Points-Table'!$A$10), 'Points-Table'!$C$10, (Q4 = 'Points-Table'!$A$11), 'Points-Table'!$C$11, (Q4 = 'Points-Table'!$A$12), 'Points-Table'!$C$12, (Q4 = 'Points-Table'!$A$13), 'Points-Table'!$C$13, true, 0 ) -> 0 | T4: =Ifs( (S4 = 'Points-Table'!$A$4), 'Points-Table'!$C$4, (S4 = 'Points-Table'!$A$5), 'Points-Table'!$C$5, (S4 = 'Points-Table'!$A$6), 'Points-Table'!$C$6, (S4 = 'Points-Table'!$A$7), 'Points-Table'!$C$7, (S4 = 'Points-Table'!$A$8), 'Points-Table'!$C$8, (S4 = 'Points-Table'!$A$9), 'Points-Table'!$C$9, (S4 = 'Points-Table'!$A$10), 'Points-Table'!$C$10, (S4 = 'Points-Table'!$A$11), 'Points-Table'!$C$11, (S4 = 'Points-Table'!$A$12), 'Points-Table'!$C$12, (S4 = 'Points-Table'!$A$13), 'Points-Table'!$C$13, true, 0 ) -> 0 | U4: 3 | V4: =Ifs( (U4 = 'Points-Table'!$A$4), 'Points-Table'!$C$4, (U4 = 'Points-Table'!$A$5), 'Points-Table'!$C$5, (U4 = 'Points-Table'!$A$6), 'Points-Table'!$C$6, (U4 = 'Points-Table'!$A$7), 'Points-Table'!$C$7, (U4 = 'Points-Table'!$A$8), 'Points-Table'!$C$8, (U4 = 'Points-Table'!$A$9), 'Points-Table'!$C$9, (U4 = 'Points-Table'!$A$10), 'Points-Table'!$C$10, (U4 = 'Points-Table'!$A$11), 'Points-Table'!$C$11, (U4 = 'Points-Table'!$A$12), 'Points-Table'!$C$12, (U4 = 'Points-Table'!$A$13), 'Points-Table'!$C$13, true, 0 ) -> 2 | W4: 5 | X4: =Ifs( (W4 = 'Points-Table'!$A$4), 'Points-Table'!$C$4, (W4 = 'Points-Table'!$A$5), 'Points-Table'!$C$5, (W4 = 'Points-Table'!$A$6), 'Points-Table'!$C$6, (W4 = 'Points-Table'!$A$7), 'Points-Table'!$C$7, (W4 = 'Points-Table'!$A$8), 'Points-Table'!$C$8, (W4 = 'Points-Table'!$A$9), 'Points-Table'!$C$9, (W4 = 'Points-Table'!$A$10), 'Points-Table'!$C$10, (W4 = 'Points-Table'!$A$11), 'Points-Table'!$C$11, (W4 = 'Points-Table'!$A$12), 'Points-Table'!$C$12, (W4 = 'Points-Table'!$A$13), 'Points-Table'!$C$13, true, 0 ) -> 4 | Y4: 8 | Z4: =Ifs( (Y4 = 'Points-Table'!$A$4), 'Points-Table'!$C$4, (Y4 = 'Points-Table'!$A$5), 'Points-Table'!$C$5, (Y4 = 'Points-Table'!$A$6), 'Points-Table'!$C$6, (Y4 = 'Points-Table'!$A$7), 'Points-Table'!$C$7, (Y4 = 'Points-Table'!$A$8), 'Points-Table'!$C$8, (Y4 = 'Points-Table'!$A$9), 'Points-Table'!$C$9, (Y4 = 'Points-Table'!$A$10), 'Points-Table'!$C$10, (Y4 = 'Points-Table'!$A$11), 'Points-Table'!$C$11, (Y4 = 'Points-Table'!$A$12), 'Points-Table'!$C$12, (Y4 = 'Points-Table'!$A$13), 'Points-Table'!$C$13, true, 0 ) -> 7 | AA4: =SUM(V4,X4,Z4) -> 13 | AB4: =IFERROR(__xludf.DUMMYFUNCTION(" Ifs( ISBETWEEN(AA4, 0, 'Points-Table'!C$20, TRUE, False), 'Points-Table'!A$20, ISBETWEEN(AA4, 'Points-Table'!C$20, 'Points-Table'!C$21, TRUE, False), 'Points-Table'!A$21, ISBETWEEN(AA4, 'Points-Table'!C$22, 10000, TRUE, TRU"&"E), 'Points-Table'!A$22, true, 0) "),"S") -> S
A5: Registration | B5: T&C | Privacy Policy confirmation | K5: Simple | L5: Must Have | R5: =Ifs( (Q5 = 'Points-Table'!$A$4), 'Points-Table'!$C$4, (Q5 = 'Points-Table'!$A$5), 'Points-Table'!$C$5, (Q5 = 'Points-Table'!$A$6), 'Points-Table'!$C$6, (Q5 = 'Points-Table'!$A$7), 'Points-Table'!$C$7, (Q5 = 'Points-Table'!$A$8), 'Points-Table'!$C$8, (Q5 = 'Points-Table'!$A$9), 'Points-Table'!$C$9, (Q5 = 'Points-Table'!$A$10), 'Points-Table'!$C$10, (Q5 = 'Points-Table'!$A$11), 'Points-Table'!$C$11, (Q5 = 'Points-Table'!$A$12), 'Points-Table'!$C$12, (Q5 = 'Points-Table'!$A$13), 'Points-Table'!$C$13, true, 0 ) -> 0 | T5: =Ifs( (S5 = 'Points-Table'!$A$4), 'Points-Table'!$C$4, (S5 = 'Points-Table'!$A$5), 'Points-Table'!$C$5, (S5 = 'Points-Table'!$A$6), 'Points-Table'!$C$6, (S5 = 'Points-Table'!$A$7), 'Points-Table'!$C$7, (S5 = 'Points-Table'!$A$8), 'Points-Table'!$C$8, (S5 = 'Points-Table'!$A$9), 'Points-Table'!$C$9, (S5 = 'Points-Table'!$A$10), 'Points-Table'!$C$10, (S5 = 'Points-Table'!$A$11), 'Points-Table'!$C$11, (S5 = 'Points-Table'!$A$12), 'Points-Table'!$C$12, (S5 = 'Points-Table'!$A$13), 'Points-Table'!$C$13, true, 0 ) -> 0 | U5: 2 | V5: =Ifs( (U5 = 'Points-Table'!$A$4), 'Points-Table'!$C$4, (U5 = 'Points-Table'!$A$5), 'Points-Table'!$C$5, (U5 = 'Points-Table'!$A$6), 'Points-Table'!$C$6, (U5 = 'Points-Table'!$A$7), 'Points-Table'!$C$7, (U5 = 'Points-Table'!$A$8), 'Points-Table'!$C$8, (U5 = 'Points-Table'!$A$9), 'Points-Table'!$C$9, (U5 = 'Points-Table'!$A$10), 'Points-Table'!$C$10, (U5 = 'Points-Table'!$A$11), 'Points-Table'!$C$11, (U5 = 'Points-Table'!$A$12), 'Points-Table'!$C$12, (U5 = 'Points-Table'!$A$13), 'Points-Table'!$C$13, true, 0 ) -> 1 | X5: =Ifs( (W5 = 'Points-Table'!$A$4), 'Points-Table'!$C$4, (W5 = 'Points-Table'!$A$5), 'Points-Table'!$C$5, (W5 = 'Points-Table'!$A$6), 'Points-Table'!$C$6, (W5 = 'Points-Table'!$A$7), 'Points-Table'!$C$7, (W5 = 'Points-Table'!$A$8), 'Points-Table'!$C$8, (W5 = 'Points-Table'!$A$9), 'Points-Table'!$C$9, (W5 = 'Points-Table'!$A$10), 'Points-Table'!$C$10, (W5 = 'Points-Table'!$A$11), 'Points-Table'!$C$11, (W5 = 'Points-Table'!$A$12), 'Points-Table'!$C$12, (W5 = 'Points-Table'!$A$13), 'Points-Table'!$C$13, true, 0 ) -> 0 | Z5: =Ifs( (Y5 = 'Points-Table'!$A$4), 'Points-Table'!$C$4, (Y5 = 'Points-Table'!$A$5), 'Points-Table'!$C$5, (Y5 = 'Points-Table'!$A$6), 'Points-Table'!$C$6, (Y5 = 'Points-Table'!$A$7), 'Points-Table'!$C$7, (Y5 = 'Points-Table'!$A$8), 'Points-Table'!$C$8, (Y5 = 'Points-Table'!$A$9), 'Points-Table'!$C$9, (Y5 = 'Points-Table'!$A$10), 'Points-Table'!$C$10, (Y5 = 'Points-Table'!$A$11), 'Points-Table'!$C$11, (Y5 = 'Points-Table'!$A$12), 'Points-Table'!$C$12, (Y5 = 'Points-Table'!$A$13), 'Points-Table'!$C$13, true, 0 ) -> 0 | AA5: =SUM(V5,X5,Z5) -> 1 | AB5: =IFERROR(__xludf.DUMMYFUNCTION(" Ifs( ISBETWEEN(AA5, 0, 'Points-Table'!C$20, TRUE, False), 'Points-Table'!A$20, ISBETWEEN(AA5, 'Points-Table'!C$20, 'Points-Table'!C$21, TRUE, False), 'Points-Table'!A$21, ISBETWEEN(AA5, 'Points-Table'!C$22, 10000, TRUE, TRU"&"E), 'Points-Table'!A$22, true, 0) "),"S") -> S
A6: Registration | B6: Social Sign In | C6: Google | K6: Simple | L6: Must Have | R6: =Ifs( (Q6 = 'Points-Table'!$A$4), 'Points-Table'!$C$4, (Q6 = 'Points-Table'!$A$5), 'Points-Table'!$C$5, (Q6 = 'Points-Table'!$A$6), 'Points-Table'!$C$6, (Q6 = 'Points-Table'!$A$7), 'Points-Table'!$C$7, (Q6 = 'Points-Table'!$A$8), 'Points-Table'!$C$8, (Q6 = 'Points-Table'!$A$9), 'Points-Table'!$C$9, (Q6 = 'Points-Table'!$A$10), 'Points-Table'!$C$10, (Q6 = 'Points-Table'!$A$11), 'Points-Table'!$C$11, (Q6 = 'Points-Table'!$A$12), 'Points-Table'!$C$12, (Q6 = 'Points-Table'!$A$13), 'Points-Table'!$C$13, true, 0 ) -> 0 | T6: =Ifs( (S6 = 'Points-Table'!$A$4), 'Points-Table'!$C$4, (S6 = 'Points-Table'!$A$5), 'Points-Table'!$C$5, (S6 = 'Points-Table'!$A$6), 'Points-Table'!$C$6, (S6 = 'Points-Table'!$A$7), 'Points-Table'!$C$7, (S6 = 'Points-Table'!$A$8), 'Points-Table'!$C$8, (S6 = 'Points-Table'!$A$9), 'Points-Table'!$C$9, (S6 = 'Points-Table'!$A$10), 'Points-Table'!$C$10, (S6 = 'Points-Table'!$A$11), 'Points-Table'!$C$11, (S6 = 'Points-Table'!$A$12), 'Points-Table'!$C$12, (S6 = 'Points-Table'!$A$13), 'Points-Table'!$C$13, true, 0 ) -> 0 | U6: 3 | V6: =Ifs( (U6 = 'Points-Table'!$A$4), 'Points-Table'!$C$4, (U6 = 'Points-Table'!$A$5), 'Points-Table'!$C$5, (U6 = 'Points-Table'!$A$6), 'Points-Table'!$C$6, (U6 = 'Points-Table'!$A$7), 'Points-Table'!$C$7, (U6 = 'Points-Table'!$A$8), 'Points-Table'!$C$8, (U6 = 'Points-Table'!$A$9), 'Points-Table'!$C$9, (U6 = 'Points-Table'!$A$10), 'Points-Table'!$C$10, (U6 = 'Points-Table'!$A$11), 'Points-Table'!$C$11, (U6 = 'Points-Table'!$A$12), 'Points-Table'!$C$12, (U6 = 'Points-Table'!$A$13), 'Points-Table'!$C$13, true, 0 ) -> 2 | W6: 8 | X6: =Ifs( (W6 = 'Points-Table'!$A$4), 'Points-Table'!$C$4, (W6 = 'Points-Table'!$A$5), 'Points-Table'!$C$5, (W6 = 'Points-Table'!$A$6), 'Points-Table'!$C$6, (W6 = 'Points-Table'!$A$7), 'Points-Table'!$C$7, (W6 = 'Points-Table'!$A$8), 'Points-Table'!$C$8, (W6 = 'Points-Table'!$A$9), 'Points-Table'!$C$9, (W6 = 'Points-Table'!$A$10), 'Points-Table'!$C$10, (W6 = 'Points-Table'!$A$11), 'Points-Table'!$C$11, (W6 = 'Points-Table'!$A$12), 'Points-Table'!$C$12, (W6 = 'Points-Table'!$A$13), 'Points-Table'!$C$13, true, 0 ) -> 7 | Y6: 8 | Z6: =Ifs( (Y6 = 'Points-Table'!$A$4), 'Points-Table'!$C$4, (Y6 = 'Points-Table'!$A$5), 'Points-Table'!$C$5, (Y6 = 'Points-Table'!$A$6), 'Points-Table'!$C$6, (Y6 = 'Points-Table'!$A$7), 'Points-Table'!$C$7, (Y6 = 'Points-Table'!$A$8), 'Points-Table'!$C$8, (Y6 = 'Points-Table'!$A$9), 'Points-Table'!$C$9, (Y6 = 'Points-Table'!$A$10), 'Points-Table'!$C$10, (Y6 = 'Points-Table'!$A$11), 'Points-Table'!$C$11, (Y6 = 'Points-Table'!$A$12), 'Points-Table'!$C$12, (Y6 = 'Points-Table'!$A$13), 'Points-Table'!$C$13, true, 0 ) -> 7 | AA6: =SUM(V6,X6,Z6) -> 16 | AB6: =IFERROR(__xludf.DUMMYFUNCTION(" Ifs( ISBETWEEN(AA6, 0, 'Points-Table'!C$20, TRUE, False), 'Points-Table'!A$20, ISBETWEEN(AA6, 'Points-Table'!C$20, 'Points-Table'!C$21, TRUE, False), 'Points-Table'!A$21, ISBETWEEN(AA6, 'Points-Table'!C$22, 10000, TRUE, TRU"&"E), 'Points-Table'!A$22, true, 0) "),"S") -> S
A7: Registration | B7: Social Sign In | C7: Facebook | K7: Simple | L7: Must Have | R7: =Ifs( (Q7 = 'Points-Table'!$A$4), 'Points-Table'!$C$4, (Q7 = 'Points-Table'!$A$5), 'Points-Table'!$C$5, (Q7 = 'Points-Table'!$A$6), 'Points-Table'!$C$6, (Q7 = 'Points-Table'!$A$7), 'Points-Table'!$C$7, (Q7 = 'Points-Table'!$A$8), 'Points-Table'!$C$8, (Q7 = 'Points-Table'!$A$9), 'Points-Table'!$C$9, (Q7 = 'Points-Table'!$A$10), 'Points-Table'!$C$10, (Q7 = 'Points-Table'!$A$11), 'Points-Table'!$C$11, (Q7 = 'Points-Table'!$A$12), 'Points-Table'!$C$12, (Q7 = 'Points-Table'!$A$13), 'Points-Table'!$C$13, true, 0 ) -> 0 | T7: =Ifs( (S7 = 'Points-Table'!$A$4), 'Points-Table'!$C$4, (S7 = 'Points-Table'!$A$5), 'Points-Table'!$C$5, (S7 = 'Points-Table'!$A$6), 'Points-Table'!$C$6, (S7 = 'Points-Table'!$A$7), 'Points-Table'!$C$7, (S7 = 'Points-Table'!$A$8), 'Points-Table'!$C$8, (S7 = 'Points-Table'!$A$9), 'Points-Table'!$C$9, (S7 = 'Points-Table'!$A$10), 'Points-Table'!$C$10, (S7 = 'Points-Table'!$A$11), 'Points-Table'!$C$11, (S7 = 'Points-Table'!$A$12), 'Points-Table'!$C$12, (S7 = 'Points-Table'!$A$13), 'Points-Table'!$C$13, true, 0 ) -> 0 | U7: 3 | V7: =Ifs( (U7 = 'Points-Table'!$A$4), 'Points-Table'!$C$4, (U7 = 'Points-Table'!$A$5), 'Points-Table'!$C$5, (U7 = 'Points-Table'!$A$6), 'Points-Table'!$C$6, (U7 = 'Points-Table'!$A$7), 'Points-Table'!$C$7, (U7 = 'Points-Table'!$A$8), 'Points-Table'!$C$8, (U7 = 'Points-Table'!$A$9), 'Points-Table'!$C$9, (U7 = 'Points-Table'!$A$10), 'Points-Table'!$C$10, (U7 = 'Points-Table'!$A$11), 'Points-Table'!$C$11, (U7 = 'Points-Table'!$A$12), 'Points-Table'!$C$12, (U7 = 'Points-Table'!$A$13), 'Points-Table'!$C$13, true, 0 ) -> 2 | W7: 13 | X7: =Ifs( (W7 = 'Points-Table'!$A$4), 'Points-Table'!$C$4, (W7 = 'Points-Table'!$A$5), 'Points-Table'!$C$5, (W7 = 'Points-Table'!$A$6), 'Points-Table'!$C$6, (W7 = 'Points-Table'!$A$7), 'Points-Table'!$C$7, (W7 = 'Points-Table'!$A$8), 'Points-Table'!$C$8, (W7 = 'Points-Table'!$A$9), 'Points-Table'!$C$9, (W7 = 'Points-Table'!$A$10), 'Points-Table'!$C$10, (W7 = 'Points-Table'!$A$11), 'Points-Table'!$C$11, (W7 = 'Points-Table'!$A$12), 'Points-Table'!$C$12, (W7 = 'Points-Table'!$A$13), 'Points-Table'!$C$13, true, 0 ) -> 11 | Z7: =Ifs( (Y7 = 'Points-Table'!$A$4), 'Points-Table'!$C$4, (Y7 = 'Points-Table'!$A$5), 'Points-Table'!$C$5, (Y7 = 'Points-Table'!$A$6), 'Points-Table'!$C$6, (Y7 = 'Points-Table'!$A$7), 'Points-Table'!$C$7, (Y7 = 'Points-Table'!$A$8), 'Points-Table'!$C$8, (Y7 = 'Points-Table'!$A$9), 'Points-Table'!$C$9, (Y7 = 'Points-Table'!$A$10), 'Points-Table'!$C$10, (Y7 = 'Points-Table'!$A$11), 'Points-Table'!$C$11, (Y7 = 'Points-Table'!$A$12), 'Points-Table'!$C$12, (Y7 = 'Points-Table'!$A$13), 'Points-Table'!$C$13, true, 0 ) -> 0 | AA7: =SUM(V7,X7,Z7) -> 13 | AB7: =IFERROR(__xludf.DUMMYFUNCTION(" Ifs( ISBETWEEN(AA7, 0, 'Points-Table'!C$20, TRUE, False), 'Points-Table'!A$20, ISBETWEEN(AA7, 'Points-Table'!C$20, 'Points-Table'!C$21, TRUE, False), 'Points-Table'!A$21, ISBETWEEN(AA7, 'Points-Table'!C$22, 10000, TRUE, TRU"&"E), 'Points-Table'!A$22, true, 0) "),"S") -> S
A8: Registration | B8: Social Sign In | C8: Linkedin | K8: Simple | L8: Must Have | R8: =Ifs( (Q8 = 'Points-Table'!$A$4), 'Points-Table'!$C$4, (Q8 = 'Points-Table'!$A$5), 'Points-Table'!$C$5, (Q8 = 'Points-Table'!$A$6), 'Points-Table'!$C$6, (Q8 = 'Points-Table'!$A$7), 'Points-Table'!$C$7, (Q8 = 'Points-Table'!$A$8), 'Points-Table'!$C$8, (Q8 = 'Points-Table'!$A$9), 'Points-Table'!$C$9, (Q8 = 'Points-Table'!$A$10), 'Points-Table'!$C$10, (Q8 = 'Points-Table'!$A$11), 'Points-Table'!$C$11, (Q8 = 'Points-Table'!$A$12), 'Points-Table'!$C$12, (Q8 = 'Points-Table'!$A$13), 'Points-Table'!$C$13, true, 0 ) -> 0 | T8: =Ifs( (S8 = 'Points-Table'!$A$4), 'Points-Table'!$C$4, (S8 = 'Points-Table'!$A$5), 'Points-Table'!$C$5, (S8 = 'Points-Table'!$A$6), 'Points-Table'!$C$6, (S8 = 'Points-Table'!$A$7), 'Points-Table'!$C$7, (S8 = 'Points-Table'!$A$8), 'Points-Table'!$C$8, (S8 = 'Points-Table'!$A$9), 'Points-Table'!$C$9, (S8 = 'Points-Table'!$A$10), 'Points-Table'!$C$10, (S8 = 'Points-Table'!$A$11), 'Points-Table'!$C$11, (S8 = 'Points-Table'!$A$12), 'Points-Table'!$C$12, (S8 = 'Points-Table'!$A$13), 'Points-Table'!$C$13, true, 0 ) -> 0 | U8: 3 | V8: =Ifs( (U8 = 'Points-Table'!$A$4), 'Points-Table'!$C$4, (U8 = 'Points-Table'!$A$5), 'Points-Table'!$C$5, (U8 = 'Points-Table'!$A$6), 'Points-Table'!$C$6, (U8 = 'Points-Table'!$A$7), 'Points-Table'!$C$7, (U8 = 'Points-Table'!$A$8), 'Points-Table'!$C$8, (U8 = 'Points-Table'!$A$9), 'Points-Table'!$C$9, (U8 = 'Points-Table'!$A$10), 'Points-Table'!$C$10, (U8 = 'Points-Table'!$A$11), 'Points-Table'!$C$11, (U8 = 'Points-Table'!$A$12), 'Points-Table'!$C$12, (U8 = 'Points-Table'!$A$13), 'Points-Table'!$C$13, true, 0 ) -> 2 | W8: 13 | X8: =Ifs( (W8 = 'Points-Table'!$A$4), 'Points-Table'!$C$4, (W8 = 'Points-Table'!$A$5), 'Points-Table'!$C$5, (W8 = 'Points-Table'!$A$6), 'Points-Table'!$C$6, (W8 = 'Points-Table'!$A$7), 'Points-Table'!$C$7, (W8 = 'Points-Table'!$A$8), 'Points-Table'!$C$8, (W8 = 'Points-Table'!$A$9), 'Points-Table'!$C$9, (W8 = 'Points-Table'!$A$10), 'Points-Table'!$C$10, (W8 = 'Points-Table'!$A$11), 'Points-Table'!$C$11, (W8 = 'Points-Table'!$A$12), 'Points-Table'!$C$12, (W8 = 'Points-Table'!$A$13), 'Points-Table'!$C$13, true, 0 ) -> 11 | Z8: =Ifs( (Y8 = 'Points-Table'!$A$4), 'Points-Table'!$C$4, (Y8 = 'Points-Table'!$A$5), 'Points-Table'!$C$5, (Y8 = 'Points-Table'!$A$6), 'Points-Table'!$C$6, (Y8 = 'Points-Table'!$A$7), 'Points-Table'!$C$7, (Y8 = 'Points-Table'!$A$8), 'Points-Table'!$C$8, (Y8 = 'Points-Table'!$A$9), 'Points-Table'!$C$9, (Y8 = 'Points-Table'!$A$10), 'Points-Table'!$C$10, (Y8 = 'Points-Table'!$A$11), 'Points-Table'!$C$11, (Y8 = 'Points-Table'!$A$12), 'Points-Table'!$C$12, (Y8 = 'Points-Table'!$A$13), 'Points-Table'!$C$13, true, 0 ) -> 0 | AA8: =SUM(V8,X8,Z8) -> 13 | AB8: =IFERROR(__xludf.DUMMYFUNCTION(" Ifs( ISBETWEEN(AA8, 0, 'Points-Table'!C$20, TRUE, False), 'Points-Table'!A$20, ISBETWEEN(AA8, 'Points-Table'!C$20, 'Points-Table'!C$21, TRUE, False), 'Points-Table'!A$21, ISBETWEEN(AA8, 'Points-Table'!C$22, 10000, TRUE, TRU"&"E), 'Points-Table'!A$22, true, 0) "),"S") -> S
A9: Login | B9: Email | OTP Verification | K9: Simple | L9: Must Have | Q9: 2 | R9: =Ifs( (Q9 = 'Points-Table'!$A$4), 'Points-Table'!$C$4, (Q9 = 'Points-Table'!$A$5), 'Points-Table'!$C$5, (Q9 = 'Points-Table'!$A$6), 'Points-Table'!$C$6, (Q9 = 'Points-Table'!$A$7), 'Points-Table'!$C$7, (Q9 = 'Points-Table'!$A$8), 'Points-Table'!$C$8, (Q9 = 'Points-Table'!$A$9), 'Points-Table'!$C$9, (Q9 = 'Points-Table'!$A$10), 'Points-Table'!$C$10, (Q9 = 'Points-Table'!$A$11), 'Points-Table'!$C$11, (Q9 = 'Points-Table'!$A$12), 'Points-Table'!$C$12, (Q9 = 'Points-Table'!$A$13), 'Points-Table'!$C$13, true, 0 ) -> 1 | S9: 2 | T9: =Ifs( (S9 = 'Points-Table'!$A$4), 'Points-Table'!$C$4, (S9 = 'Points-Table'!$A$5), 'Points-Table'!$C$5, (S9 = 'Points-Table'!$A$6), 'Points-Table'!$C$6, (S9 = 'Points-Table'!$A$7), 'Points-Table'!$C$7, (S9 = 'Points-Table'!$A$8), 'Points-Table'!$C$8, (S9 = 'Points-Table'!$A$9), 'Points-Table'!$C$9, (S9 = 'Points-Table'!$A$10), 'Points-Table'!$C$10, (S9 = 'Points-Table'!$A$11), 'Points-Table'!$C$11, (S9 = 'Points-Table'!$A$12), 'Points-Table'!$C$12, (S9 = 'Points-Table'!$A$13), 'Points-Table'!$C$13, true, 0 ) -> 1 | U9: 5 | V9: =Ifs( (U9 = 'Points-Table'!$A$4), 'Points-Table'!$C$4, (U9 = 'Points-Table'!$A$5), 'Points-Table'!$C$5, (U9 = 'Points-Table'!$A$6), 'Points-Table'!$C$6, (U9 = 'Points-Table'!$A$7), 'Points-Table'!$C$7, (U9 = 'Points-Table'!$A$8), 'Points-Table'!$C$8, (U9 = 'Points-Table'!$A$9), 'Points-Table'!$C$9, (U9 = 'Points-Table'!$A$10), 'Points-Table'!$C$10, (U9 = 'Points-Table'!$A$11), 'Points-Table'!$C$11, (U9 = 'Points-Table'!$A$12), 'Points-Table'!$C$12, (U9 = 'Points-Table'!$A$13), 'Points-Table'!$C$13, true, 0 ) -> 4 | W9: 8 | X9: =Ifs( (W9 = 'Points-Table'!$A$4), 'Points-Table'!$C$4, (W9 = 'Points-Table'!$A$5), 'Points-Table'!$C$5, (W9 = 'Points-Table'!$A$6), 'Points-Table'!$C$6, (W9 = 'Points-Table'!$A$7), 'Points-Table'!$C$7, (W9 = 'Points-Table'!$A$8), 'Points-Table'!$C$8, (W9 = 'Points-Table'!$A$9), 'Points-Table'!$C$9, (W9 = 'Points-Table'!$A$10), 'Points-Table'!$C$10, (W9 = 'Points-Table'!$A$11), 'Points-Table'!$C$11, (W9 = 'Points-Table'!$A$12), 'Points-Table'!$C$12, (W9 = 'Points-Table'!$A$13), 'Points-Table'!$C$13, true, 0 ) -> 7 | Y9: 5 | Z9: =Ifs( (Y9 = 'Points-Table'!$A$4), 'Points-Table'!$C$4, (Y9 = 'Points-Table'!$A$5), 'Points-Table'!$C$5, (Y9 = 'Points-Table'!$A$6), 'Points-Table'!$C$6, (Y9 = 'Points-Table'!$A$7), 'Points-Table'!$C$7, (Y9 = 'Points-Table'!$A$8), 'Points-Table'!$C$8, (Y9 = 'Points-Table'!$A$9), 'Points-Table'!$C$9, (Y9 = 'Points-Table'!$A$10), 'Points-Table'!$C$10, (Y9 = 'Points-Table'!$A$11), 'Points-Table'!$C$11, (Y9 = 'Points-Table'!$A$12), 'Points-Table'!$C$12, (Y9 = 'Points-Table'!$A$13), 'Points-Table'!$C$13, true, 0 ) -> 4 | AA9: =SUM(V9,X9,Z9) -> 15 | AB9: =IFERROR(__xludf.DUMMYFUNCTION(" Ifs( ISBETWEEN(AA9, 0, 'Points-Table'!C$20, TRUE, False), 'Points-Table'!A$20, ISBETWEEN(AA9, 'Points-Table'!C$20, 'Points-Table'!C$21, TRUE, False), 'Points-Table'!A$21, ISBETWEEN(AA9, 'Points-Table'!C$22, 10000, TRUE, TRU"&"E), 'Points-Table'!A$22, true, 0) "),"S") -> S
A10: Login | B10: Social Login | C10: Google | K10: Simple | L10: Must Have | R10: =Ifs( (Q10 = 'Points-Table'!$A$4), 'Points-Table'!$C$4, (Q10 = 'Points-Table'!$A$5), 'Points-Table'!$C$5, (Q10 = 'Points-Table'!$A$6), 'Points-Table'!$C$6, (Q10 = 'Points-Table'!$A$7), 'Points-Table'!$C$7, (Q10 = 'Points-Table'!$A$8), 'Points-Table'!$C$8, (Q10 = 'Points-Table'!$A$9), 'Points-Table'!$C$9, (Q10 = 'Points-Table'!$A$10), 'Points-Table'!$C$10, (Q10 = 'Points-Table'!$A$11), 'Points-Table'!$C$11, (Q10 = 'Points-Table'!$A$12), 'Points-Table'!$C$12, (Q10 = 'Points-Table'!$A$13), 'Points-Table'!$C$13, true, 0 ) -> 0 | T10: =Ifs( (S10 = 'Points-Table'!$A$4), 'Points-Table'!$C$4, (S10 = 'Points-Table'!$A$5), 'Points-Table'!$C$5, (S10 = 'Points-Table'!$A$6), 'Points-Table'!$C$6, (S10 = 'Points-Table'!$A$7), 'Points-Table'!$C$7, (S10 = 'Points-Table'!$A$8), 'Points-Table'!$C$8, (S10 = 'Points-Table'!$A$9), 'Points-Table'!$C$9, (S10 = 'Points-Table'!$A$10), 'Points-Table'!$C$10, (S10 = 'Points-Table'!$A$11), 'Points-Table'!$C$11, (S10 = 'Points-Table'!$A$12), 'Points-Table'!$C$12, (S10 = 'Points-Table'!$A$13), 'Points-Table'!$C$13, true, 0 ) -> 0 | U10: 3 | V10: =Ifs( (U10 = 'Points-Table'!$A$4), 'Points-Table'!$C$4, (U10 = 'Points-Table'!$A$5), 'Points-Table'!$C$5, (U10 = 'Points-Table'!$A$6), 'Points-Table'!$C$6, (U10 = 'Points-Table'!$A$7), 'Points-Table'!$C$7, (U10 = 'Points-Table'!$A$8), 'Points-Table'!$C$8, (U10 = 'Points-Table'!$A$9), 'Points-Table'!$C$9, (U10 = 'Points-Table'!$A$10), 'Points-Table'!$C$10, (U10 = 'Points-Table'!$A$11), 'Points-Table'!$C$11, (U10 = 'Points-Table'!$A$12), 'Points-Table'!$C$12, (U10 = 'Points-Table'!$A$13), 'Points-Table'!$C$13, true, 0 ) -> 2 | W10: 8 | X10: =Ifs( (W10 = 'Points-Table'!$A$4), 'Points-Table'!$C$4, (W10 = 'Points-Table'!$A$5), 'Points-Table'!$C$5, (W10 = 'Points-Table'!$A$6), 'Points-Table'!$C$6, (W10 = 'Points-Table'!$A$7), 'Points-Table'!$C$7, (W10 = 'Points-Table'!$A$8), 'Points-Table'!$C$8, (W10 = 'Points-Table'!$A$9), 'Points-Table'!$C$9, (W10 = 'Points-Table'!$A$10), 'Points-Table'!$C$10, (W10 = 'Points-Table'!$A$11), 'Points-Table'!$C$11, (W10 = 'Points-Table'!$A$12), 'Points-Table'!$C$12, (W10 = 'Points-Table'!$A$13), 'Points-Table'!$C$13, true, 0 ) -> 7 | Z10: =Ifs( (Y10 = 'Points-Table'!$A$4), 'Points-Table'!$C$4, (Y10 = 'Points-Table'!$A$5), 'Points-Table'!$C$5, (Y10 = 'Points-Table'!$A$6), 'Points-Table'!$C$6, (Y10 = 'Points-Table'!$A$7), 'Points-Table'!$C$7, (Y10 = 'Points-Table'!$A$8), 'Points-Table'!$C$8, (Y10 = 'Points-Table'!$A$9), 'Points-Table'!$C$9, (Y10 = 'Points-Table'!$A$10), 'Points-Table'!$C$10, (Y10 = 'Points-Table'!$A$11), 'Points-Table'!$C$11, (Y10 = 'Points-Table'!$A$12), 'Points-Table'!$C$12, (Y10 = 'Points-Table'!$A$13), 'Points-Table'!$C$13, true, 0 ) -> 0 | AA10: =SUM(V10,X10,Z10) -> 9 | AB10: =IFERROR(__xludf.DUMMYFUNCTION(" Ifs( ISBETWEEN(AA10, 0, 'Points-Table'!C$20, TRUE, False), 'Points-Table'!A$20, ISBETWEEN(AA10, 'Points-Table'!C$20, 'Points-Table'!C$21, TRUE, False), 'Points-Table'!A$21, ISBETWEEN(AA10, 'Points-Table'!C$22, 10000, TRUE, "&"TRUE), 'Points-Table'!A$22, true, 0) "),"S") -> S
A11: Login | B11: Social Login | C11: Facebook | K11: Simple | L11: Must Have | R11: =Ifs( (Q11 = 'Points-Table'!$A$4), 'Points-Table'!$C$4, (Q11 = 'Points-Table'!$A$5), 'Points-Table'!$C$5, (Q11 = 'Points-Table'!$A$6), 'Points-Table'!$C$6, (Q11 = 'Points-Table'!$A$7), 'Points-Table'!$C$7, (Q11 = 'Points-Table'!$A$8), 'Points-Table'!$C$8, (Q11 = 'Points-Table'!$A$9), 'Points-Table'!$C$9, (Q11 = 'Points-Table'!$A$10), 'Points-Table'!$C$10, (Q11 = 'Points-Table'!$A$11), 'Points-Table'!$C$11, (Q11 = 'Points-Table'!$A$12), 'Points-Table'!$C$12, (Q11 = 'Points-Table'!$A$13), 'Points-Table'!$C$13, true, 0 ) -> 0 | T11: =Ifs( (S11 = 'Points-Table'!$A$4), 'Points-Table'!$C$4, (S11 = 'Points-Table'!$A$5), 'Points-Table'!$C$5, (S11 = 'Points-Table'!$A$6), 'Points-Table'!$C$6, (S11 = 'Points-Table'!$A$7), 'Points-Table'!$C$7, (S11 = 'Points-Table'!$A$8), 'Points-Table'!$C$8, (S11 = 'Points-Table'!$A$9), 'Points-Table'!$C$9, (S11 = 'Points-Table'!$A$10), 'Points-Table'!$C$10, (S11 = 'Points-Table'!$A$11), 'Points-Table'!$C$11, (S11 = 'Points-Table'!$A$12), 'Points-Table'!$C$12, (S11 = 'Points-Table'!$A$13), 'Points-Table'!$C$13, true, 0 ) -> 0 | U11: 3 | V11: =Ifs( (U11 = 'Points-Table'!$A$4), 'Points-Table'!$C$4, (U11 = 'Points-Table'!$A$5), 'Points-Table'!$C$5, (U11 = 'Points-Table'!$A$6), 'Points-Table'!$C$6, (U11 = 'Points-Table'!$A$7), 'Points-Table'!$C$7, (U11 = 'Points-Table'!$A$8), 'Points-Table'!$C$8, (U11 = 'Points-Table'!$A$9), 'Points-Table'!$C$9, (U11 = 'Points-Table'!$A$10), 'Points-Table'!$C$10, (U11 = 'Points-Table'!$A$11), 'Points-Table'!$C$11, (U11 = 'Points-Table'!$A$12), 'Points-Table'!$C$12, (U11 = 'Points-Table'!$A$13), 'Points-Table'!$C$13, true, 0 ) -> 2 | W11: 13 | X11: =Ifs( (W11 = 'Points-Table'!$A$4), 'Points-Table'!$C$4, (W11 = 'Points-Table'!$A$5), 'Points-Table'!$C$5, (W11 = 'Points-Table'!$A$6), 'Points-Table'!$C$6, (W11 = 'Points-Table'!$A$7), 'Points-Table'!$C$7, (W11 = 'Points-Table'!$A$8), 'Points-Table'!$C$8, (W11 = 'Points-Table'!$A$9), 'Points-Table'!$C$9, (W11 = 'Points-Table'!$A$10), 'Points-Table'!$C$10, (W11 = 'Points-Table'!$A$11), 'Points-Table'!$C$11, (W11 = 'Points-Table'!$A$12), 'Points-Table'!$C$12, (W11 = 'Points-Table'!$A$13), 'Points-Table'!$C$13, true, 0 ) -> 11 | Z11: =Ifs( (Y11 = 'Points-Table'!$A$4), 'Points-Table'!$C$4, (Y11 = 'Points-Table'!$A$5), 'Points-Table'!$C$5, (Y11 = 'Points-Table'!$A$6), 'Points-Table'!$C$6, (Y11 = 'Points-Table'!$A$7), 'Points-Table'!$C$7, (Y11 = 'Points-Table'!$A$8), 'Points-Table'!$C$8, (Y11 = 'Points-Table'!$A$9), 'Points-Table'!$C$9, (Y11 = 'Points-Table'!$A$10), 'Points-Table'!$C$10, (Y11 = 'Points-Table'!$A$11), 'Points-Table'!$C$11, (Y11 = 'Points-Table'!$A$12), 'Points-Table'!$C$12, (Y11 = 'Points-Table'!$A$13), 'Points-Table'!$C$13, true, 0 ) -> 0 | AA11: =SUM(V11,X11,Z11) -> 13 | AB11: =IFERROR(__xludf.DUMMYFUNCTION(" Ifs( ISBETWEEN(AA11, 0, 'Points-Table'!C$20, TRUE, False), 'Points-Table'!A$20, ISBETWEEN(AA11, 'Points-Table'!C$20, 'Points-Table'!C$21, TRUE, False), 'Points-Table'!A$21, ISBETWEEN(AA11, 'Points-Table'!C$22, 10000, TRUE, "&"TRUE), 'Points-Table'!A$22, true, 0) "),"S") -> S
A12: Login | B12: Social Login | C12: LinkedIn | K12: Simple | L12: Must Have | R12: =Ifs( (Q12 = 'Points-Table'!$A$4), 'Points-Table'!$C$4, (Q12 = 'Points-Table'!$A$5), 'Points-Table'!$C$5, (Q12 = 'Points-Table'!$A$6), 'Points-Table'!$C$6, (Q12 = 'Points-Table'!$A$7), 'Points-Table'!$C$7, (Q12 = 'Points-Table'!$A$8), 'Points-Table'!$C$8, (Q12 = 'Points-Table'!$A$9), 'Points-Table'!$C$9, (Q12 = 'Points-Table'!$A$10), 'Points-Table'!$C$10, (Q12 = 'Points-Table'!$A$11), 'Points-Table'!$C$11, (Q12 = 'Points-Table'!$A$12), 'Points-Table'!$C$12, (Q12 = 'Points-Table'!$A$13), 'Points-Table'!$C$13, true, 0 ) -> 0 | T12: =Ifs( (S12 = 'Points-Table'!$A$4), 'Points-Table'!$C$4, (S12 = 'Points-Table'!$A$5), 'Points-Table'!$C$5, (S12 = 'Points-Table'!$A$6), 'Points-Table'!$C$6, (S12 = 'Points-Table'!$A$7), 'Points-Table'!$C$7, (S12 = 'Points-Table'!$A$8), 'Points-Table'!$C$8, (S12 = 'Points-Table'!$A$9), 'Points-Table'!$C$9, (S12 = 'Points-Table'!$A$10), 'Points-Table'!$C$10, (S12 = 'Points-Table'!$A$11), 'Points-Table'!$C$11, (S12 = 'Points-Table'!$A$12), 'Points-Table'!$C$12, (S12 = 'Points-Table'!$A$13), 'Points-Table'!$C$13, true, 0 ) -> 0 | U12: 3 | V12: =Ifs( (U12 = 'Points-Table'!$A$4), 'Points-Table'!$C$4, (U12 = 'Points-Table'!$A$5), 'Points-Table'!$C$5, (U12 = 'Points-Table'!$A$6), 'Points-Table'!$C$6, (U12 = 'Points-Table'!$A$7), 'Points-Table'!$C$7, (U12 = 'Points-Table'!$A$8), 'Points-Table'!$C$8, (U12 = 'Points-Table'!$A$9), 'Points-Table'!$C$9, (U12 = 'Points-Table'!$A$10), 'Points-Table'!$C$10, (U12 = 'Points-Table'!$A$11), 'Points-Table'!$C$11, (U12 = 'Points-Table'!$A$12), 'Points-Table'!$C$12, (U12 = 'Points-Table'!$A$13), 'Points-Table'!$C$13, true, 0 ) -> 2 | W12: 13 | X12: =Ifs( (W12 = 'Points-Table'!$A$4), 'Points-Table'!$C$4, (W12 = 'Points-Table'!$A$5), 'Points-Table'!$C$5, (W12 = 'Points-Table'!$A$6), 'Points-Table'!$C$6, (W12 = 'Points-Table'!$A$7), 'Points-Table'!$C$7, (W12 = 'Points-Table'!$A$8), 'Points-Table'!$C$8, (W12 = 'Points-Table'!$A$9), 'Points-Table'!$C$9, (W12 = 'Points-Table'!$A$10), 'Points-Table'!$C$10, (W12 = 'Points-Table'!$A$11), 'Points-Table'!$C$11, (W12 = 'Points-Table'!$A$12), 'Points-Table'!$C$12, (W12 = 'Points-Table'!$A$13), 'Points-Table'!$C$13, true, 0 ) -> 11 | Z12: =Ifs( (Y12 = 'Points-Table'!$A$4), 'Points-Table'!$C$4, (Y12 = 'Points-Table'!$A$5), 'Points-Table'!$C$5, (Y12 = 'Points-Table'!$A$6), 'Points-Table'!$C$6, (Y12 = 'Points-Table'!$A$7), 'Points-Table'!$C$7, (Y12 = 'Points-Table'!$A$8), 'Points-Table'!$C$8, (Y12 = 'Points-Table'!$A$9), 'Points-Table'!$C$9, (Y12 = 'Points-Table'!$A$10), 'Points-Table'!$C$10, (Y12 = 'Points-Table'!$A$11), 'Points-Table'!$C$11, (Y12 = 'Points-Table'!$A$12), 'Points-Table'!$C$12, (Y12 = 'Points-Table'!$A$13), 'Points-Table'!$C$13, true, 0 ) -> 0 | AA12: =SUM(V12,X12,Z12) -> 13 | AB12: =IFERROR(__xludf.DUMMYFUNCTION(" Ifs( ISBETWEEN(AA12, 0, 'Points-Table'!C$20, TRUE, False), 'Points-Table'!A$20, ISBETWEEN(AA12, 'Points-Table'!C$20, 'Points-Table'!C$21, TRUE, False), 'Points-Table'!A$21, ISBETWEEN(AA12, 'Points-Table'!C$22, 10000, TRUE, "&"TRUE), 'Points-Table'!A$22, true, 0) "),"S") -> S
A13: Login | B13: Forget | Reset Password | K13: Simple | L13: Must Have | R13: =Ifs( (Q13 = 'Points-Table'!$A$4), 'Points-Table'!$C$4, (Q13 = 'Points-Table'!$A$5), 'Points-Table'!$C$5, (Q13 = 'Points-Table'!$A$6), 'Points-Table'!$C$6, (Q13 = 'Points-Table'!$A$7), 'Points-Table'!$C$7, (Q13 = 'Points-Table'!$A$8), 'Points-Table'!$C$8, (Q13 = 'Points-Table'!$A$9), 'Points-Table'!$C$9, (Q13 = 'Points-Table'!$A$10), 'Points-Table'!$C$10, (Q13 = 'Points-Table'!$A$11), 'Points-Table'!$C$11, (Q13 = 'Points-Table'!$A$12), 'Points-Table'!$C$12, (Q13 = 'Points-Table'!$A$13), 'Points-Table'!$C$13, true, 0 ) -> 0 | T13: =Ifs( (S13 = 'Points-Table'!$A$4), 'Points-Table'!$C$4, (S13 = 'Points-Table'!$A$5), 'Points-Table'!$C$5, (S13 = 'Points-Table'!$A$6), 'Points-Table'!$C$6, (S13 = 'Points-Table'!$A$7), 'Points-Table'!$C$7, (S13 = 'Points-Table'!$A$8), 'Points-Table'!$C$8, (S13 = 'Points-Table'!$A$9), 'Points-Table'!$C$9, (S13 = 'Points-Table'!$A$10), 'Points-Table'!$C$10, (S13 = 'Points-Table'!$A$11), 'Points-Table'!$C$11, (S13 = 'Points-Table'!$A$12), 'Points-Table'!$C$12, (S13 = 'Points-Table'!$A$13), 'Points-Table'!$C$13, true, 0 ) -> 0 | U13: 5 | V13: =Ifs( (U13 = 'Points-Table'!$A$4), 'Points-Table'!$C$4, (U13 = 'Points-Table'!$A$5), 'Points-Table'!$C$5, (U13 = 'Points-Table'!$A$6), 'Points-Table'!$C$6, (U13 = 'Points-Table'!$A$7), 'Points-Table'!$C$7, (U13 = 'Points-Table'!$A$8), 'Points-Table'!$C$8, (U13 = 'Points-Table'!$A$9), 'Points-Table'!$C$9, (U13 = 'Points-Table'!$A$10), 'Points-Table'!$C$10, (U13 = 'Points-Table'!$A$11), 'Points-Table'!$C$11, (U13 = 'Points-Table'!$A$12), 'Points-Table'!$C$12, (U13 = 'Points-Table'!$A$13), 'Points-Table'!$C$13, true, 0 ) -> 4 | W13: 13 | X13: =Ifs( (W13 = 'Points-Table'!$A$4), 'Points-Table'!$C$4, (W13 = 'Points-Table'!$A$5), 'Points-Table'!$C$5, (W13 = 'Points-Table'!$A$6), 'Points-Table'!$C$6, (W13 = 'Points-Table'!$A$7), 'Points-Table'!$C$7, (W13 = 'Points-Table'!$A$8), 'Points-Table'!$C$8, (W13 = 'Points-Table'!$A$9), 'Points-Table'!$C$9, (W13 = 'Points-Table'!$A$10), 'Points-Table'!$C$10, (W13 = 'Points-Table'!$A$11), 'Points-Table'!$C$11, (W13 = 'Points-Table'!$A$12), 'Points-Table'!$C$12, (W13 = 'Points-Table'!$A$13), 'Points-Table'!$C$13, true, 0 ) -> 11 | Y13: 5 | Z13: =Ifs( (Y13 = 'Points-Table'!$A$4), 'Points-Table'!$C$4, (Y13 = 'Points-Table'!$A$5), 'Points-Table'!$C$5, (Y13 = 'Points-Table'!$A$6), 'Points-Table'!$C$6, (Y13 = 'Points-Table'!$A$7), 'Points-Table'!$C$7, (Y13 = 'Points-Table'!$A$8), 'Points-Table'!$C$8, (Y13 = 'Points-Table'!$A$9), 'Points-Table'!$C$9, (Y13 = 'Points-Table'!$A$10), 'Points-Table'!$C$10, (Y13 = 'Points-Table'!$A$11), 'Points-Table'!$C$11, (Y13 = 'Points-Table'!$A$12), 'Points-Table'!$C$12, (Y13 = 'Points-Table'!$A$13), 'Points-Table'!$C$13, true, 0 ) -> 4 | AA13: =SUM(V13,X13,Z13) -> 19 | AB13: =IFERROR(__xludf.DUMMYFUNCTION(" Ifs( ISBETWEEN(AA13, 0, 'Points-Table'!C$20, TRUE, False), 'Points-Table'!A$20, ISBETWEEN(AA13, 'Points-Table'!C$20, 'Points-Table'!C$21, TRUE, False), 'Points-Table'!A$21, ISBETWEEN(AA13, 'Points-Table'!C$22, 10000, TRUE, "&"TRUE), 'Points-Table'!A$22, true, 0) "),"S") -> S
A14: User Onboarding | B14: Create Profile (Form) | C14: Basic Details | K14: Simple | L14: Must Have | Q14: 2 | R14: =Ifs( (Q14 = 'Points-Table'!$A$4), 'Points-Table'!$C$4, (Q14 = 'Points-Table'!$A$5), 'Points-Table'!$C$5, (Q14 = 'Points-Table'!$A$6), 'Points-Table'!$C$6, (Q14 = 'Points-Table'!$A$7), 'Points-Table'!$C$7, (Q14 = 'Points-Table'!$A$8), 'Points-Table'!$C$8, (Q14 = 'Points-Table'!$A$9), 'Points-Table'!$C$9, (Q14 = 'Points-Table'!$A$10), 'Points-Table'!$C$10, (Q14 = 'Points-Table'!$A$11), 'Points-Table'!$C$11, (Q14 = 'Points-Table'!$A$12), 'Points-Table'!$C$12, (Q14 = 'Points-Table'!$A$13), 'Points-Table'!$C$13, true, 0 ) -> 1 | S14: 2 | T14: =Ifs( (S14 = 'Points-Table'!$A$4), 'Points-Table'!$C$4, (S14 = 'Points-Table'!$A$5), 'Points-Table'!$C$5, (S14 = 'Points-Table'!$A$6), 'Points-Table'!$C$6, (S14 = 'Points-Table'!$A$7), 'Points-Table'!$C$7, (S14 = 'Points-Table'!$A$8), 'Points-Table'!$C$8, (S14 = 'Points-Table'!$A$9), 'Points-Table'!$C$9, (S14 = 'Points-Table'!$A$10), 'Points-Table'!$C$10, (S14 = 'Points-Table'!$A$11), 'Points-Table'!$C$11, (S14 = 'Points-Table'!$A$12), 'Points-Table'!$C$12, (S14 = 'Points-Table'!$A$13), 'Points-Table'!$C$13, true, 0 ) -> 1 | U14: 2 | V14: =Ifs( (U14 = 'Points-Table'!$A$4), 'Points-Table'!$C$4, (U14 = 'Points-Table'!$A$5), 'Points-Table'!$C$5, (U14 = 'Points-Table'!$A$6), 'Points-Table'!$C$6, (U14 = 'Points-Table'!$A$7), 'Points-Table'!$C$7, (U14 = 'Points-Table'!$A$8), 'Points-Table'!$C$8, (U14 = 'Points-Table'!$A$9), 'Points-Table'!$C$9, (U14 = 'Points-Table'!$A$10), 'Points-Table'!$C$10, (U14 = 'Points-Table'!$A$11), 'Points-Table'!$C$11, (U14 = 'Points-Table'!$A$12), 'Points-Table'!$C$12, (U14 = 'Points-Table'!$A$13), 'Points-Table'!$C$13, true, 0 ) -> 1 | W14: 2 | X14: =Ifs( (W14 = 'Points-Table'!$A$4), 'Points-Table'!$C$4, (W14 = 'Points-Table'!$A$5), 'Points-Table'!$C$5, (W14 = 'Points-Table'!$A$6), 'Points-Table'!$C$6, (W14 = 'Points-Table'!$A$7), 'Points-Table'!$C$7, (W14 = 'Points-Table'!$A$8), 'Points-Table'!$C$8, (W14 = 'Points-Table'!$A$9), 'Points-Table'!$C$9, (W14 = 'Points-Table'!$A$10), 'Points-Table'!$C$10, (W14 = 'Points-Table'!$A$11), 'Points-Table'!$C$11, (W14 = 'Points-Table'!$A$12), 'Points-Table'!$C$12, (W14 = 'Points-Table'!$A$13), 'Points-Table'!$C$13, true, 0 ) -> 1 | Y14: 8 | Z14: =Ifs( (Y14 = 'Points-Table'!$A$4), 'Points-Table'!$C$4, (Y14 = 'Points-Table'!$A$5), 'Points-Table'!$C$5, (Y14 = 'Points-Table'!$A$6), 'Points-Table'!$C$6, (Y14 = 'Points-Table'!$A$7), 'Points-Table'!$C$7, (Y14 = 'Points-Table'!$A$8), 'Points-Table'!$C$8, (Y14 = 'Points-Table'!$A$9), 'Points-Table'!$C$9, (Y14 = 'Points-Table'!$A$10), 'Points-Table'!$C$10, (Y14 = 'Points-Table'!$A$11), 'Points-Table'!$C$11, (Y14 = 'Points-Table'!$A$12), 'Points-Table'!$C$12, (Y14 = 'Points-Table'!$A$13), 'Points-Table'!$C$13, true, 0 ) -> 7 | AA14: =SUM(V14,X14,Z14) -> 9 | AB14: =IFERROR(__xludf.DUMMYFUNCTION(" Ifs( ISBETWEEN(AA14, 0, 'Points-Table'!C$20, TRUE, False), 'Points-Table'!A$20, ISBETWEEN(AA14, 'Points-Table'!C$20, 'Points-Table'!C$21, TRUE, False), 'Points-Table'!A$21, ISBETWEEN(AA14, 'Points-Table'!C$22, 10000, TRUE, "&"TRUE), 'Points-Table'!A$22, true, 0) "),"S") -> S
A15: User Onboarding | B15: Create Profile (Form) | C15: Add video Intro | D15: YT/Vimeo Link (Embed Code from YT/Vimeo) | K15: Simple | L15: Must Have | Q15: 2 | R15: =Ifs( (Q15 = 'Points-Table'!$A$4), 'Points-Table'!$C$4, (Q15 = 'Points-Table'!$A$5), 'Points-Table'!$C$5, (Q15 = 'Points-Table'!$A$6), 'Points-Table'!$C$6, (Q15 = 'Points-Table'!$A$7), 'Points-Table'!$C$7, (Q15 = 'Points-Table'!$A$8), 'Points-Table'!$C$8, (Q15 = 'Points-Table'!$A$9), 'Points-Table'!$C$9, (Q15 = 'Points-Table'!$A$10), 'Points-Table'!$C$10, (Q15 = 'Points-Table'!$A$11), 'Points-Table'!$C$11, (Q15 = 'Points-Table'!$A$12), 'Points-Table'!$C$12, (Q15 = 'Points-Table'!$A$13), 'Points-Table'!$C$13, true, 0 ) -> 1 | S15: 2 | T15: =Ifs( (S15 = 'Points-Table'!$A$4), 'Points-Table'!$C$4, (S15 = 'Points-Table'!$A$5), 'Points-Table'!$C$5, (S15 = 'Points-Table'!$A$6), 'Points-Table'!$C$6, (S15 = 'Points-Table'!$A$7), 'Points-Table'!$C$7, (S15 = 'Points-Table'!$A$8), 'Points-Table'!$C$8, (S15 = 'Points-Table'!$A$9), 'Points-Table'!$C$9, (S15 = 'Points-Table'!$A$10), 'Points-Table'!$C$10, (S15 = 'Points-Table'!$A$11), 'Points-Table'!$C$11, (S15 = 'Points-Table'!$A$12), 'Points-Table'!$C$12, (S15 = 'Points-Table'!$A$13), 'Points-Table'!$C$13, true, 0 ) -> 1 | U15: 2 | V15: =Ifs( (U15 = 'Points-Table'!$A$4), 'Points-Table'!$C$4, (U15 = 'Points-Table'!$A$5), 'Points-Table'!$C$5, (U15 = 'Points-Table'!$A$6), 'Points-Table'!$C$6, (U15 = 'Points-Table'!$A$7), 'Points-Table'!$C$7, (U15 = 'Points-Table'!$A$8), 'Points-Table'!$C$8, (U15 = 'Points-Table'!$A$9), 'Points-Table'!$C$9, (U15 = 'Points-Table'!$A$10), 'Points-Table'!$C$10, (U15 = 'Points-Table'!$A$11), 'Points-Table'!$C$11, (U15 = 'Points-Table'!$A$12), 'Points-Table'!$C$12, (U15 = 'Points-Table'!$A$13), 'Points-Table'!$C$13, true, 0 ) -> 1 | W15: 2 | X15: =Ifs( (W15 = 'Points-Table'!$A$4), 'Points-Table'!$C$4, (W15 = 'Points-Table'!$A$5), 'Points-Table'!$C$5, (W15 = 'Points-Table'!$A$6), 'Points-Table'!$C$6, (W15 = 'Points-Table'!$A$7), 'Points-Table'!$C$7, (W15 = 'Points-Table'!$A$8), 'Points-Table'!$C$8, (W15 = 'Points-Table'!$A$9), 'Points-Table'!$C$9, (W15 = 'Points-Table'!$A$10), 'Points-Table'!$C$10, (W15 = 'Points-Table'!$A$11), 'Points-Table'!$C$11, (W15 = 'Points-Table'!$A$12), 'Points-Table'!$C$12, (W15 = 'Points-Table'!$A$13), 'Points-Table'!$C$13, true, 0 ) -> 1 | Z15: =Ifs( (Y15 = 'Points-Table'!$A$4), 'Points-Table'!$C$4, (Y15 = 'Points-Table'!$A$5), 'Points-Table'!$C$5, (Y15 = 'Points-Table'!$A$6), 'Points-Table'!$C$6, (Y15 = 'Points-Table'!$A$7), 'Points-Table'!$C$7, (Y15 = 'Points-Table'!$A$8), 'Points-Table'!$C$8, (Y15 = 'Points-Table'!$A$9), 'Points-Table'!$C$9, (Y15 = 'Points-Table'!$A$10), 'Points-Table'!$C$10, (Y15 = 'Points-Table'!$A$11), 'Points-Table'!$C$11, (Y15 = 'Points-Table'!$A$12), 'Points-Table'!$C$12, (Y15 = 'Points-Table'!$A$13), 'Points-Table'!$C$13, true, 0 ) -> 0 | AA15: =SUM(V15,X15,Z15) -> 2 | AB15: =IFERROR(__xludf.DUMMYFUNCTION(" Ifs( ISBETWEEN(AA15, 0, 'Points-Table'!C$20, TRUE, False), 'Points-Table'!A$20, ISBETWEEN(AA15, 'Points-Table'!C$20, 'Points-Table'!C$21, TRUE, False), 'Points-Table'!A$21, ISBETWEEN(AA15, 'Points-Table'!C$22, 10000, TRUE, "&"TRUE), 'Points-Table'!A$22, true, 0) "),"S") -> S
A16: User Onboarding | B16: Create Profile (Form) | C16: Website URL | K16: Simple | L16: Must Have | Q16: 2 | R16: =Ifs( (Q16 = 'Points-Table'!$A$4), 'Points-Table'!$C$4, (Q16 = 'Points-Table'!$A$5), 'Points-Table'!$C$5, (Q16 = 'Points-Table'!$A$6), 'Points-Table'!$C$6, (Q16 = 'Points-Table'!$A$7), 'Points-Table'!$C$7, (Q16 = 'Points-Table'!$A$8), 'Points-Table'!$C$8, (Q16 = 'Points-Table'!$A$9), 'Points-Table'!$C$9, (Q16 = 'Points-Table'!$A$10), 'Points-Table'!$C$10, (Q16 = 'Points-Table'!$A$11), 'Points-Table'!$C$11, (Q16 = 'Points-Table'!$A$12), 'Points-Table'!$C$12, (Q16 = 'Points-Table'!$A$13), 'Points-Table'!$C$13, true, 0 ) -> 1 | S16: 2 | T16: =Ifs( (S16 = 'Points-Table'!$A$4), 'Points-Table'!$C$4, (S16 = 'Points-Table'!$A$5), 'Points-Table'!$C$5, (S16 = 'Points-Table'!$A$6), 'Points-Table'!$C$6, (S16 = 'Points-Table'!$A$7), 'Points-Table'!$C$7, (S16 = 'Points-Table'!$A$8), 'Points-Table'!$C$8, (S16 = 'Points-Table'!$A$9), 'Points-Table'!$C$9, (S16 = 'Points-Table'!$A$10), 'Points-Table'!$C$10, (S16 = 'Points-Table'!$A$11), 'Points-Table'!$C$11, (S16 = 'Points-Table'!$A$12), 'Points-Table'!$C$12, (S16 = 'Points-Table'!$A$13), 'Points-Table'!$C$13, true, 0 ) -> 1 | U16: 2 | V16: =Ifs( (U16 = 'Points-Table'!$A$4), 'Points-Table'!$C$4, (U16 = 'Points-Table'!$A$5), 'Points-Table'!$C$5, (U16 = 'Points-Table'!$A$6), 'Points-Table'!$C$6, (U16 = 'Points-Table'!$A$7), 'Points-Table'!$C$7, (U16 = 'Points-Table'!$A$8), 'Points-Table'!$C$8, (U16 = 'Points-Table'!$A$9), 'Points-Table'!$C$9, (U16 = 'Points-Table'!$A$10), 'Points-Table'!$C$10, (U16 = 'Points-Table'!$A$11), 'Points-Table'!$C$11, (U16 = 'Points-Table'!$A$12), 'Points-Table'!$C$12, (U16 = 'Points-Table'!$A$13), 'Points-Table'!$C$13, true, 0 ) -> 1 | W16: 2 | X16: =Ifs( (W16 = 'Points-Table'!$A$4), 'Points-Table'!$C$4, (W16 = 'Points-Table'!$A$5), 'Points-Table'!$C$5, (W16 = 'Points-Table'!$A$6), 'Points-Table'!$C$6, (W16 = 'Points-Table'!$A$7), 'Points-Table'!$C$7, (W16 = 'Points-Table'!$A$8), 'Points-Table'!$C$8, (W16 = 'Points-Table'!$A$9), 'Points-Table'!$C$9, (W16 = 'Points-Table'!$A$10), 'Points-Table'!$C$10, (W16 = 'Points-Table'!$A$11), 'Points-Table'!$C$11, (W16 = 'Points-Table'!$A$12), 'Points-Table'!$C$12, (W16 = 'Points-Table'!$A$13), 'Points-Table'!$C$13, true, 0 ) -> 1 | Z16: =Ifs( (Y16 = 'Points-Table'!$A$4), 'Points-Table'!$C$4, (Y16 = 'Points-Table'!$A$5), 'Points-Table'!$C$5, (Y16 = 'Points-Table'!$A$6), 'Points-Table'!$C$6, (Y16 = 'Points-Table'!$A$7), 'Points-Table'!$C$7, (Y16 = 'Points-Table'!$A$8), 'Points-Table'!$C$8, (Y16 = 'Points-Table'!$A$9), 'Points-Table'!$C$9, (Y16 = 'Points-Table'!$A$10), 'Points-Table'!$C$10, (Y16 = 'Points-Table'!$A$11), 'Points-Table'!$C$11, (Y16 = 'Points-Table'!$A$12), 'Points-Table'!$C$12, (Y16 = 'Points-Table'!$A$13), 'Points-Table'!$C$13, true, 0 ) -> 0 | AA16: =SUM(V16,X16,Z16) -> 2 | AB16: =IFERROR(__xludf.DUMMYFUNCTION(" Ifs( ISBETWEEN(AA16, 0, 'Points-Table'!C$20, TRUE, False), 'Points-Table'!A$20, ISBETWEEN(AA16, 'Points-Table'!C$20, 'Points-Table'!C$21, TRUE, False), 'Points-Table'!A$21, ISBETWEEN(AA16, 'Points-Table'!C$22, 10000, TRUE, "&"TRUE), 'Points-Table'!A$22, true, 0) "),"S") -> S
A17: User Onboarding | B17: Create Profile (Form) | C17: Education Level | K17: Simple | L17: Must Have | Q17: 0 | R17: =Ifs( (Q17 = 'Points-Table'!$A$4), 'Points-Table'!$C$4, (Q17 = 'Points-Table'!$A$5), 'Points-Table'!$C$5, (Q17 = 'Points-Table'!$A$6), 'Points-Table'!$C$6, (Q17 = 'Points-Table'!$A$7), 'Points-Table'!$C$7, (Q17 = 'Points-Table'!$A$8), 'Points-Table'!$C$8, (Q17 = 'Points-Table'!$A$9), 'Points-Table'!$C$9, (Q17 = 'Points-Table'!$A$10), 'Points-Table'!$C$10, (Q17 = 'Points-Table'!$A$11), 'Points-Table'!$C$11, (Q17 = 'Points-Table'!$A$12), 'Points-Table'!$C$12, (Q17 = 'Points-Table'!$A$13), 'Points-Table'!$C$13, true, 0 ) -> 0 | S17: 0 | T17: =Ifs( (S17 = 'Points-Table'!$A$4), 'Points-Table'!$C$4, (S17 = 'Points-Table'!$A$5), 'Points-Table'!$C$5, (S17 = 'Points-Table'!$A$6), 'Points-Table'!$C$6, (S17 = 'Points-Table'!$A$7), 'Points-Table'!$C$7, (S17 = 'Points-Table'!$A$8), 'Points-Table'!$C$8, (S17 = 'Points-Table'!$A$9), 'Points-Table'!$C$9, (S17 = 'Points-Table'!$A$10), 'Points-Table'!$C$10, (S17 = 'Points-Table'!$A$11), 'Points-Table'!$C$11, (S17 = 'Points-Table'!$A$12), 'Points-Table'!$C$12, (S17 = 'Points-Table'!$A$13), 'Points-Table'!$C$13, true, 0 ) -> 0 | U17: 2 | V17: =Ifs( (U17 = 'Points-Table'!$A$4), 'Points-Table'!$C$4, (U17 = 'Points-Table'!$A$5), 'Points-Table'!$C$5, (U17 = 'Points-Table'!$A$6), 'Points-Table'!$C$6, (U17 = 'Points-Table'!$A$7), 'Points-Table'!$C$7, (U17 = 'Points-Table'!$A$8), 'Points-Table'!$C$8, (U17 = 'Points-Table'!$A$9), 'Points-Table'!$C$9, (U17 = 'Points-Table'!$A$10), 'Points-Table'!$C$10, (U17 = 'Points-Table'!$A$11), 'Points-Table'!$C$11, (U17 = 'Points-Table'!$A$12), 'Points-Table'!$C$12, (U17 = 'Points-Table'!$A$13), 'Points-Table'!$C$13, true, 0 ) -> 1 | W17: 2 | X17: =Ifs( (W17 = 'Points-Table'!$A$4), 'Points-Table'!$C$4, (W17 = 'Points-Table'!$A$5), 'Points-Table'!$C$5, (W17 = 'Points-Table'!$A$6), 'Points-Table'!$C$6, (W17 = 'Points-Table'!$A$7), 'Points-Table'!$C$7, (W17 = 'Points-Table'!$A$8), 'Points-Table'!$C$8, (W17 = 'Points-Table'!$A$9), 'Points-Table'!$C$9, (W17 = 'Points-Table'!$A$10), 'Points-Table'!$C$10, (W17 = 'Points-Table'!$A$11), 'Points-Table'!$C$11, (W17 = 'Points-Table'!$A$12), 'Points-Table'!$C$12, (W17 = 'Points-Table'!$A$13), 'Points-Table'!$C$13, true, 0 ) -> 1 | Z17: =Ifs( (Y17 = 'Points-Table'!$A$4), 'Points-Table'!$C$4, (Y17 = 'Points-Table'!$A$5), 'Points-Table'!$C$5, (Y17 = 'Points-Table'!$A$6), 'Points-Table'!$C$6, (Y17 = 'Points-Table'!$A$7), 'Points-Table'!$C$7, (Y17 = 'Points-Table'!$A$8), 'Points-Table'!$C$8, (Y17 = 'Points-Table'!$A$9), 'Points-Table'!$C$9, (Y17 = 'Points-Table'!$A$10), 'Points-Table'!$C$10, (Y17 = 'Points-Table'!$A$11), 'Points-Table'!$C$11, (Y17 = 'Points-Table'!$A$12), 'Points-Table'!$C$12, (Y17 = 'Points-Table'!$A$13), 'Points-Table'!$C$13, true, 0 ) -> 0 | AA17: =SUM(V17,X17,Z17) -> 2 | AB17: =IFERROR(__xludf.DUMMYFUNCTION(" Ifs( ISBETWEEN(AA17, 0, 'Points-Table'!C$20, TRUE, False), 'Points-Table'!A$20, ISBETWEEN(AA17, 'Points-Table'!C$20, 'Points-Table'!C$21, TRUE, False), 'Points-Table'!A$21, ISBETWEEN(AA17, 'Points-Table'!C$22, 10000, TRUE, "&"TRUE), 'Points-Table'!A$22, true, 0) "),"S") -> S
A18: User Onboarding | B18: Create Profile (Form) | C18: Social Links | K18: Simple | L18: Must Have | R18: =Ifs( (Q18 = 'Points-Table'!$A$4), 'Points-Table'!$C$4, (Q18 = 'Points-Table'!$A$5), 'Points-Table'!$C$5, (Q18 = 'Points-Table'!$A$6), 'Points-Table'!$C$6, (Q18 = 'Points-Table'!$A$7), 'Points-Table'!$C$7, (Q18 = 'Points-Table'!$A$8), 'Points-Table'!$C$8, (Q18 = 'Points-Table'!$A$9), 'Points-Table'!$C$9, (Q18 = 'Points-Table'!$A$10), 'Points-Table'!$C$10, (Q18 = 'Points-Table'!$A$11), 'Points-Table'!$C$11, (Q18 = 'Points-Table'!$A$12), 'Points-Table'!$C$12, (Q18 = 'Points-Table'!$A$13), 'Points-Table'!$C$13, true, 0 ) -> 0 | T18: =Ifs( (S18 = 'Points-Table'!$A$4), 'Points-Table'!$C$4, (S18 = 'Points-Table'!$A$5), 'Points-Table'!$C$5, (S18 = 'Points-Table'!$A$6), 'Points-Table'!$C$6, (S18 = 'Points-Table'!$A$7), 'Points-Table'!$C$7, (S18 = 'Points-Table'!$A$8), 'Points-Table'!$C$8, (S18 = 'Points-Table'!$A$9), 'Points-Table'!$C$9, (S18 = 'Points-Table'!$A$10), 'Points-Table'!$C$10, (S18 = 'Points-Table'!$A$11), 'Points-Table'!$C$11, (S18 = 'Points-Table'!$A$12), 'Points-Table'!$C$12, (S18 = 'Points-Table'!$A$13), 'Points-Table'!$C$13, true, 0 ) -> 0 | U18: 2 | V18: =Ifs( (U18 = 'Points-Table'!$A$4), 'Points-Table'!$C$4, (U18 = 'Points-Table'!$A$5), 'Points-Table'!$C$5, (U18 = 'Points-Table'!$A$6), 'Points-Table'!$C$6, (U18 = 'Points-Table'!$A$7), 'Points-Table'!$C$7, (U18 = 'Points-Table'!$A$8), 'Points-Table'!$C$8, (U18 = 'Points-Table'!$A$9), 'Points-Table'!$C$9, (U18 = 'Points-Table'!$A$10), 'Points-Table'!$C$10, (U18 = 'Points-Table'!$A$11), 'Points-Table'!$C$11, (U18 = 'Points-Table'!$A$12), 'Points-Table'!$C$12, (U18 = 'Points-Table'!$A$13), 'Points-Table'!$C$13, true, 0 ) -> 1 | W18: 2 | X18: =Ifs( (W18 = 'Points-Table'!$A$4), 'Points-Table'!$C$4, (W18 = 'Points-Table'!$A$5), 'Points-Table'!$C$5, (W18 = 'Points-Table'!$A$6), 'Points-Table'!$C$6, (W18 = 'Points-Table'!$A$7), 'Points-Table'!$C$7, (W18 = 'Points-Table'!$A$8), 'Points-Table'!$C$8, (W18 = 'Points-Table'!$A$9), 'Points-Table'!$C$9, (W18 = 'Points-Table'!$A$10), 'Points-Table'!$C$10, (W18 = 'Points-Table'!$A$11), 'Points-Table'!$C$11, (W18 = 'Points-Table'!$A$12), 'Points-Table'!$C$12, (W18 = 'Points-Table'!$A$13), 'Points-Table'!$C$13, true, 0 ) -> 1 | Z18: =Ifs( (Y18 = 'Points-Table'!$A$4), 'Points-Table'!$C$4, (Y18 = 'Points-Table'!$A$5), 'Points-Table'!$C$5, (Y18 = 'Points-Table'!$A$6), 'Points-Table'!$C$6, (Y18 = 'Points-Table'!$A$7), 'Points-Table'!$C$7, (Y18 = 'Points-Table'!$A$8), 'Points-Table'!$C$8, (Y18 = 'Points-Table'!$A$9), 'Points-Table'!$C$9, (Y18 = 'Points-Table'!$A$10), 'Points-Table'!$C$10, (Y18 = 'Points-Table'!$A$11), 'Points-Table'!$C$11, (Y18 = 'Points-Table'!$A$12), 'Points-Table'!$C$12, (Y18 = 'Points-Table'!$A$13), 'Points-Table'!$C$13, true, 0 ) -> 0 | AA18: =SUM(V18,X18,Z18) -> 2 | AB18: =IFERROR(__xludf.DUMMYFUNCTION(" Ifs( ISBETWEEN(AA18, 0, 'Points-Table'!C$20, TRUE, False), 'Points-Table'!A$20, ISBETWEEN(AA18, 'Points-Table'!C$20, 'Points-Table'!C$21, TRUE, False), 'Points-Table'!A$21, ISBETWEEN(AA18, 'Points-Table'!C$22, 10000, TRUE, "&"TRUE), 'Points-Table'!A$22, true, 0) "),"S") -> S
A19: User Onboarding | B19: Create Profile (Form) | C19: Bio - Short & Long Bio (Text) | K19: Simple | L19: Must Have | R19: =Ifs( (Q19 = 'Points-Table'!$A$4), 'Points-Table'!$C$4, (Q19 = 'Points-Table'!$A$5), 'Points-Table'!$C$5, (Q19 = 'Points-Table'!$A$6), 'Points-Table'!$C$6, (Q19 = 'Points-Table'!$A$7), 'Points-Table'!$C$7, (Q19 = 'Points-Table'!$A$8), 'Points-Table'!$C$8, (Q19 = 'Points-Table'!$A$9), 'Points-Table'!$C$9, (Q19 = 'Points-Table'!$A$10), 'Points-Table'!$C$10, (Q19 = 'Points-Table'!$A$11), 'Points-Table'!$C$11, (Q19 = 'Points-Table'!$A$12), 'Points-Table'!$C$12, (Q19 = 'Points-Table'!$A$13), 'Points-Table'!$C$13, true, 0 ) -> 0 | T19: =Ifs( (S19 = 'Points-Table'!$A$4), 'Points-Table'!$C$4, (S19 = 'Points-Table'!$A$5), 'Points-Table'!$C$5, (S19 = 'Points-Table'!$A$6), 'Points-Table'!$C$6, (S19 = 'Points-Table'!$A$7), 'Points-Table'!$C$7, (S19 = 'Points-Table'!$A$8), 'Points-Table'!$C$8, (S19 = 'Points-Table'!$A$9), 'Points-Table'!$C$9, (S19 = 'Points-Table'!$A$10), 'Points-Table'!$C$10, (S19 = 'Points-Table'!$A$11), 'Points-Table'!$C$11, (S19 = 'Points-Table'!$A$12), 'Points-Table'!$C$12, (S19 = 'Points-Table'!$A$13), 'Points-Table'!$C$13, true, 0 ) -> 0 | U19: 2 | V19: =Ifs( (U19 = 'Points-Table'!$A$4), 'Points-Table'!$C$4, (U19 = 'Points-Table'!$A$5), 'Points-Table'!$C$5, (U19 = 'Points-Table'!$A$6), 'Points-Table'!$C$6, (U19 = 'Points-Table'!$A$7), 'Points-Table'!$C$7, (U19 = 'Points-Table'!$A$8), 'Points-Table'!$C$8, (U19 = 'Points-Table'!$A$9), 'Points-Table'!$C$9, (U19 = 'Points-Table'!$A$10), 'Points-Table'!$C$10, (U19 = 'Points-Table'!$A$11), 'Points-Table'!$C$11, (U19 = 'Points-Table'!$A$12), 'Points-Table'!$C$12, (U19 = 'Points-Table'!$A$13), 'Points-Table'!$C$13, true, 0 ) -> 1 | W19: 2 | X19: =Ifs( (W19 = 'Points-Table'!$A$4), 'Points-Table'!$C$4, (W19 = 'Points-Table'!$A$5), 'Points-Table'!$C$5, (W19 = 'Points-Table'!$A$6), 'Points-Table'!$C$6, (W19 = 'Points-Table'!$A$7), 'Points-Table'!$C$7, (W19 = 'Points-Table'!$A$8), 'Points-Table'!$C$8, (W19 = 'Points-Table'!$A$9), 'Points-Table'!$C$9, (W19 = 'Points-Table'!$A$10), 'Points-Table'!$C$10, (W19 = 'Points-Table'!$A$11), 'Points-Table'!$C$11, (W19 = 'Points-Table'!$A$12), 'Points-Table'!$C$12, (W19 = 'Points-Table'!$A$13), 'Points-Table'!$C$13, true, 0 ) -> 1 | Z19: =Ifs( (Y19 = 'Points-Table'!$A$4), 'Points-Table'!$C$4, (Y19 = 'Points-Table'!$A$5), 'Points-Table'!$C$5, (Y19 = 'Points-Table'!$A$6), 'Points-Table'!$C$6, (Y19 = 'Points-Table'!$A$7), 'Points-Table'!$C$7, (Y19 = 'Points-Table'!$A$8), 'Points-Table'!$C$8, (Y19 = 'Points-Table'!$A$9), 'Points-Table'!$C$9, (Y19 = 'Points-Table'!$A$10), 'Points-Table'!$C$10, (Y19 = 'Points-Table'!$A$11), 'Points-Table'!$C$11, (Y19 = 'Points-Table'!$A$12), 'Points-Table'!$C$12, (Y19 = 'Points-Table'!$A$13), 'Points-Table'!$C$13, true, 0 ) -> 0 | AA19: =SUM(V19,X19,Z19) -> 2 | AB19: =IFERROR(__xludf.DUMMYFUNCTION(" Ifs( ISBETWEEN(AA19, 0, 'Points-Table'!C$20, TRUE, False), 'Points-Table'!A$20, ISBETWEEN(AA19, 'Points-Table'!C$20, 'Points-Table'!C$21, TRUE, False), 'Points-Table'!A$21, ISBETWEEN(AA19, 'Points-Table'!C$22, 10000, TRUE, "&"TRUE), 'Points-Table'!A$22, true, 0) "),"S") -> S
A20: User Onboarding | B20: Create Profile (Form) | C20: Upload Profile | Cover Pic | K20: Simple | L20: Must Have | R20: =Ifs( (Q20 = 'Points-Table'!$A$4), 'Points-Table'!$C$4, (Q20 = 'Points-Table'!$A$5), 'Points-Table'!$C$5, (Q20 = 'Points-Table'!$A$6), 'Points-Table'!$C$6, (Q20 = 'Points-Table'!$A$7), 'Points-Table'!$C$7, (Q20 = 'Points-Table'!$A$8), 'Points-Table'!$C$8, (Q20 = 'Points-Table'!$A$9), 'Points-Table'!$C$9, (Q20 = 'Points-Table'!$A$10), 'Points-Table'!$C$10, (Q20 = 'Points-Table'!$A$11), 'Points-Table'!$C$11, (Q20 = 'Points-Table'!$A$12), 'Points-Table'!$C$12, (Q20 = 'Points-Table'!$A$13), 'Points-Table'!$C$13, true, 0 ) -> 0 | T20: =Ifs( (S20 = 'Points-Table'!$A$4), 'Points-Table'!$C$4, (S20 = 'Points-Table'!$A$5), 'Points-Table'!$C$5, (S20 = 'Points-Table'!$A$6), 'Points-Table'!$C$6, (S20 = 'Points-Table'!$A$7), 'Points-Table'!$C$7, (S20 = 'Points-Table'!$A$8), 'Points-Table'!$C$8, (S20 = 'Points-Table'!$A$9), 'Points-Table'!$C$9, (S20 = 'Points-Table'!$A$10), 'Points-Table'!$C$10, (S20 = 'Points-Table'!$A$11), 'Points-Table'!$C$11, (S20 = 'Points-Table'!$A$12), 'Points-Table'!$C$12, (S20 = 'Points-Table'!$A$13), 'Points-Table'!$C$13, true, 0 ) -> 0 | U20: 2 | V20: =Ifs( (U20 = 'Points-Table'!$A$4), 'Points-Table'!$C$4, (U20 = 'Points-Table'!$A$5), 'Points-Table'!$C$5, (U20 = 'Points-Table'!$A$6), 'Points-Table'!$C$6, (U20 = 'Points-Table'!$A$7), 'Points-Table'!$C$7, (U20 = 'Points-Table'!$A$8), 'Points-Table'!$C$8, (U20 = 'Points-Table'!$A$9), 'Points-Table'!$C$9, (U20 = 'Points-Table'!$A$10), 'Points-Table'!$C$10, (U20 = 'Points-Table'!$A$11), 'Points-Table'!$C$11, (U20 = 'Points-Table'!$A$12), 'Points-Table'!$C$12, (U20 = 'Points-Table'!$A$13), 'Points-Table'!$C$13, true, 0 ) -> 1 | W20: 2 | X20: =Ifs( (W20 = 'Points-Table'!$A$4), 'Points-Table'!$C$4, (W20 = 'Points-Table'!$A$5), 'Points-Table'!$C$5, (W20 = 'Points-Table'!$A$6), 'Points-Table'!$C$6, (W20 = 'Points-Table'!$A$7), 'Points-Table'!$C$7, (W20 = 'Points-Table'!$A$8), 'Points-Table'!$C$8, (W20 = 'Points-Table'!$A$9), 'Points-Table'!$C$9, (W20 = 'Points-Table'!$A$10), 'Points-Table'!$C$10, (W20 = 'Points-Table'!$A$11), 'Points-Table'!$C$11, (W20 = 'Points-Table'!$A$12), 'Points-Table'!$C$12, (W20 = 'Points-Table'!$A$13), 'Points-Table'!$C$13, true, 0 ) -> 1 | Z20: =Ifs( (Y20 = 'Points-Table'!$A$4), 'Points-Table'!$C$4, (Y20 = 'Points-Table'!$A$5), 'Points-Table'!$C$5, (Y20 = 'Points-Table'!$A$6), 'Points-Table'!$C$6, (Y20 = 'Points-Table'!$A$7), 'Points-Table'!$C$7, (Y20 = 'Points-Table'!$A$8), 'Points-Table'!$C$8, (Y20 = 'Points-Table'!$A$9), 'Points-Table'!$C$9, (Y20 = 'Points-Table'!$A$10), 'Points-Table'!$C$10, (Y20 = 'Points-Table'!$A$11), 'Points-Table'!$C$11, (Y20 = 'Points-Table'!$A$12), 'Points-Table'!$C$12, (Y20 = 'Points-Table'!$A$13), 'Points-Table'!$C$13, true, 0 ) -> 0 | AA20: =SUM(V20,X20,Z20) -> 2 | AB20: =IFERROR(__xludf.DUMMYFUNCTION(" Ifs( ISBETWEEN(AA20, 0, 'Points-Table'!C$20, TRUE, False), 'Points-Table'!A$20, ISBETWEEN(AA20, 'Points-Table'!C$20, 'Points-Table'!C$21, TRUE, False), 'Points-Table'!A$21, ISBETWEEN(AA20, 'Points-Table'!C$22, 10000, TRUE, "&"TRUE), 'Points-Table'!A$22, true, 0) "),"S") -> S
